Workbook

Sheet LTP_Formulas
A1: Prod Line | B1: Project | C1: Model | D1: SEW/ASSY | E1: {=[1]PLANING!$Z63:$BV$63} -> 46041 | F1: 46048 | G1: 46055 | H1: 46062 | I1: 46069 | J1: 46076 | K1: 46083 | L1: 46090 | M1: 46097 | N1: 46104 | O1: 46111 | P1: 46118 | Q1: 46125 | R1: 46132 | S1: 46139 | T1: 46146 | U1: 46153 | V1: 46160 | W1: 46167 | X1: 46174 | Y1: 46181 | Z1: 46188 | AA1: 46195 | AB1: 46202 | AC1: 46209 | AD1: 46216 | AE1: 46223 | AF1: 46230 | AG1: 46237 | AH1: 46244 | AI1: 46251 | AJ1: 46258 | AK1: 46265 | AL1: 46272 | AM1: 46279 | AN1: 46286 | AO1: 46293 | AP1: 46300 | AQ1: 46307 | AR1: 46314 | AS1: 46321 | AT1: 46328 | AU1: 46335 | AV1: 46342 | AW1: 46349 | AX1: 46356 | AY1: 46363 | AZ1: 46370 | BA1: 46377
A2: =IF(B2="","",_xlfn.XLOOKUP(B2&"_"&C2&"_"&D2,[2]ref!$E:$E,[2]ref!$A:$A)) -> B_FG | B2: {=_xlfn._xlws.FILTER([1]PLANING!$A:$B,([1]PLANING!$D:$D="Weekly Output PLAN")*([1]PLANING!$A:$A<>"blank"))} -> DAIMLER | C2: BR223 | D2: {=_xlfn._xlws.FILTER([1]PLANING!$E:$E,([1]PLANING!$D:$D="Weekly Output PLAN")*([1]PLANING!$A:$A<>"blank"))} -> SEW | E2: {=ROUND(_xlfn._xlws.FILTER([1]PLANING!$Z:$BV,([1]PLANING!$D:$D="Weekly Output PLAN")*([1]PLANING!$A:$A<>"blank")),0)} -> 2465 | F2: 2583 | G2: 2387 | H2: 2191 | I2: 1479 | J2: 3443 | K2: 3952 | L2: 4461 | M2: 4578 | N2: 4696 | O2: 4813 | P2: 3944 | Q2: 4273 | R2: 5478 | S2: 4492 | T2: 5752 | U2: 5889 | V2: 6026 | W2: 6163 | X2: 6300 | Y2: 6437 | Z2: 6574 | AA2: 6711 | AB2: 6848 | AC2: 6985 | AD2: 7122 | AE2: 0 | AF2: 0 | AG2: 9039 | AH2: 9203 | AI2: 9368 | AJ2: 7943 | AK2: 8080 | AL2: 8217 | AM2: 8354 | AN2: 8491 | AO2: 8628 | AP2: 8765 | AQ2: 24926 | AR2: 25310 | AS2: 25693 | AT2: 16873 | AU2: 16873 | AV2: 16873 | AW2: 16873 | AX2: 16873 | AY2: 16873 | AZ2: 16873 | BA2: 16873
A3: =IF(B3="","",_xlfn.XLOOKUP(B3&"_"&C3&"_"&D3,[2]ref!$E:$E,[2]ref!$A:$A)) -> B_FG | B3: DAIMLER | C3: BR223 LTH | D3: SEW | E3: 833 | F3: 454 | G3: 492 | H3: 265 | I3: 341 | J3: 303 | K3: 644 | L3: 682 | M3: 757 | N3: 757 | O3: 1136 | P3: 909 | Q3: 909 | R3: 1136 | S3: 909 | T3: 1136 | U3: 1136 | V3: 1136 | W3: 1136 | X3: 1136 | Y3: 1136 | Z3: 1136 | AA3: 1136 | AB3: 1136 | AC3: 1136 | AD3: 1136 | AE3: 0 | AF3: 0 | AG3: 757 | AH3: 379 | AI3: 757 | AJ3: 379 | AK3: 757 | AL3: 379 | AM3: 757 | AN3: 379 | AO3: 757 | AP3: 454 | AQ3: 1363 | AR3: 454 | AS3: 1363 | AT3: 454 | AU3: 1363 | AV3: 454 | AW3: 1363 | AX3: 454 | AY3: 1363 | AZ3: 454 | BA3: 1363
A4: =IF(B4="","",_xlfn.XLOOKUP(B4&"_"&C4&"_"&D4,[2]ref!$E:$E,[2]ref!$A:$A)) -> F_FG | B4: FIAT | C4: J516 / VINYL | D4: SEW | E4: 4872 | F4: 5414 | G4: 5414 | H4: 6496 | I4: 3248 | J4: 6496 | K4: 5684 | L4: 5684 | M4: 4737 | N4: 4737 | O4: 4737 | P4: 3248 | Q4: 3248 | R4: 4060 | S4: 3248 | T4: 3722 | U4: 3722 | V4: 3722 | W4: 3722 | X4: 3722 | Y4: 3722 | Z4: 3722 | AA4: 3722 | AB4: 3722 | AC4: 3722 | AD4: 3722 | AE4: 0 | AF4: 0 | AG4: 3722 | AH4: 3722 | AI4: 3722 | AJ4: 3722 | AK4: 3722 | AL4: 3722 | AM4: 3722 | AN4: 3722 | AO4: 4060 | AP4: 7444 | AQ4: 35729 | AR4: 35729 | AS4: 35729 | AT4: 35729 | AU4: 35729 | AV4: 35729 | AW4: 35729 | AX4: 35729 | AY4: 558 | AZ4: 558 | BA4: 558
A5: =IF(B5="","",_xlfn.XLOOKUP(B5&"_"&C5&"_"&D5,[2]ref!$E:$E,[2]ref!$A:$A)) -> F_FG | B5: FIAT | C5: J516 / FABRIC | D5: SEW | E5: 652 | F5: 1087 | G5: 1087 | H5: 2174 | I5: 1304 | J5: 2174 | K5: 2536 | L5: 2536 | M5: 2536 | N5: 2536 | O5: 2536 | P5: 2029 | Q5: 2029 | R5: 2536 | S5: 2029 | T5: 2174 | U5: 2174 | V5: 2174 | W5: 2174 | X5: 2174 | Y5: 2174 | Z5: 2174 | AA5: 2174 | AB5: 2174 | AC5: 2174 | AD5: 2174 | AE5: 0 | AF5: 0 | AG5: 2174 | AH5: 2174 | AI5: 2174 | AJ5: 2174 | AK5: 2174 | AL5: 2174 | AM5: 2174 | AN5: 2174 | AO5: 2174 | AP5: 1196 | AQ5: 717 | AR5: 717 | AS5: 717 | AT5: 717 | AU5: 717 | AV5: 717 | AW5: 783 | AX5: 783 | AY5: 783 | AZ5: 783 | BA5: 783
A6: =IF(B6="","",_xlfn.XLOOKUP(B6&"_"&C6&"_"&D6,[2]ref!$E:$E,[2]ref!$A:$A)) -> P_FG | B6: PORSCHE | C6: PO426 ARM | D6: SEW | E6: 680 | F6: 340 | G6: 680 | H6: 680 | I6: 408 | J6: 680 | K6: 680 | L6: 340 | M6: 680 | N6: 340 | O6: 680 | P6: 544 | Q6: 544 | R6: 680 | S6: 544 | T6: 680 | U6: 680 | V6: 680 | W6: 680 | X6: 680 | Y6: 680 | Z6: 680 | AA6: 680 | AB6: 680 | AC6: 680 | AD6: 680 | AE6: 0 | AF6: 0 | AG6: 680 | AH6: 680 | AI6: 680 | AJ6: 680 | AK6: 680 | AL6: 680 | AM6: 680 | AN6: 680 | AO6: 680 | AP6: 1020 | AQ6: 612 | AR6: 612 | AS6: 612 | AT6: 612 | AU6: 612 | AV6: 612 | AW6: 612 | AX6: 612 | AY6: 612 | AZ6: 612 | BA6: 612
A7: =IF(B7="","",_xlfn.XLOOKUP(B7&"_"&C7&"_"&D7,[2]ref!$E:$E,[2]ref!$A:$A)) -> P_FG | B7: PORSCHE | C7: PO426 Gueset | D7: SEW | E7: 884 | F7: 2209 | G7: 2209 | H7: 1105 | I7: 663 | J7: 1105 | K7: 1105 | L7: 1105 | M7: 1105 | N7: 1105 | O7: 1105 | P7: 1768 | Q7: 1768 | R7: 1105 | S7: 1768 | T7: 1105 | U7: 2209 | V7: 1105 | W7: 2209 | X7: 1105 | Y7: 2209 | Z7: 1105 | AA7: 2209 | AB7: 1105 | AC7: 2209 | AD7: 1105 | AE7: 0 | AF7: 0 | AG7: 1105 | AH7: 2209 | AI7: 1105 | AJ7: 2209 | AK7: 1105 | AL7: 2209 | AM7: 1105 | AN7: 2209 | AO7: 2209 | AP7: 1326 | AQ7: 265 | AR7: 265 | AS7: 265 | AT7: 265 | AU7: 265 | AV7: 265 | AW7: 265 | AX7: 265 | AY7: 265 | AZ7: 265 | BA7: 265
A8: =IF(B8="","",_xlfn.XLOOKUP(B8&"_"&C8&"_"&D8,[2]ref!$E:$E,[2]ref!$A:$A)) -> P_FG | B8: PORSCHE | C8: PO426 FHR&ROHR | D8: SEW | E8: 914 | F8: 964 | G8: 1117 | H8: 1489 | I8: 893 | J8: 1489 | K8: 1489 | L8: 1117 | M8: 1015 | N8: 1015 | O8: 1015 | P8: 812 | Q8: 812 | R8: 1015 | S8: 812 | T8: 1015 | U8: 1015 | V8: 1015 | W8: 1015 | X8: 1015 | Y8: 1015 | Z8: 1015 | AA8: 1015 | AB8: 1015 | AC8: 1015 | AD8: 1015 | AE8: 0 | AF8: 0 | AG8: 677 | AH8: 1353 | AI8: 1353 | AJ8: 1353 | AK8: 1353 | AL8: 1353 | AM8: 1353 | AN8: 1353 | AO8: 1353 | AP8: 812 | AQ8: 325 | AR8: 325 | AS8: 731 | AT8: 731 | AU8: 731 | AV8: 731 | AW8: 731 | AX8: 731 | AY8: 731 | AZ8: 731 | BA8: 731
A9: =IF(B9="","",_xlfn.XLOOKUP(B9&"_"&C9&"_"&D9,[2]ref!$E:$E,[2]ref!$A:$A)) -> V_FG | B9: Volvo PIP | C9: EX30 PIP Outer | D9: SEW | E9: 2413 | F9: 2547 | G9: 3277 | H9: 3604 | I9: 1966 | J9: 3277 | K9: 3277 | L9: 3277 | M9: 3277 | N9: 3277 | O9: 3277 | P9: 2621 | Q9: 2621 | R9: 3277 | S9: 2621 | T9: 3277 | U9: 3277 | V9: 3277 | W9: 3277 | X9: 3277 | Y9: 3128 | Z9: 2979 | AA9: 2979 | AB9: 2979 | AC9: 2979 | AD9: 2979 | AE9: 0 | AF9: 0 | AG9: 2979 | AH9: 2979 | AI9: 2979 | AJ9: 2979 | AK9: 2979 | AL9: 2979 | AM9: 2979 | AN9: 2979 | AO9: 2979 | AP9: 2621 | AQ9: 4051 | AR9: 5242 | AS9: 5242 | AT9: 1072 | AU9: 1072 | AV9: 1072 | AW9: 1072 | AX9: 1072 | AY9: 1072 | AZ9: 1072 | BA9: 1072
A10: =IF(B10="","",_xlfn.XLOOKUP(B10&"_"&C10&"_"&D10,[2]ref!$E:$E,[2]ref!$A:$A)) -> V_FG | B10: Volvo PIP | C10: EX30 PIP Center | D10: SEW | E10: 633 | F10: 1001 | G10: 1650 | H10: 1650 | I10: 825 | J10: 1031 | K10: 1031 | L10: 1031 | M10: 1031 | N10: 1375 | O10: 1375 | P10: 1100 | Q10: 1100 | R10: 1375 | S10: 1100 | T10: 1375 | U10: 1031 | V10: 1031 | W10: 1031 | X10: 1031 | Y10: 1031 | Z10: 1031 | AA10: 1031 | AB10: 1031 | AC10: 1031 | AD10: 1031 | AE10: 0 | AF10: 0 | AG10: 1031 | AH10: 1031 | AI10: 1031 | AJ10: 1031 | AK10: 1031 | AL10: 1031 | AM10: 1031 | AN10: 1031 | AO10: 1031 | AP10: 0 | AQ10: 0 | AR10: 0 | AS10: 0 | AT10: 0 | AU10: 0 | AV10: 0 | AW10: 0 | AX10: 0 | AY10: 0 | AZ10: 0 | BA10: 0
A11: =IF(B11="","",_xlfn.XLOOKUP(B11&"_"&C11&"_"&D11,[2]ref!$E:$E,[2]ref!$A:$A)) -> T_FG | B11: Nissan | C11: P13A PIP | D11: SEW | E11: 0 | F11: 977 | G11: 1221 | H11: 3541 | I11: 2417 | J11: 4517 | K11: 5006 | L11: 5494 | M11: 5983 | N11: 6471 | O11: 6959 | P11: 5958 | Q11: 6349 | R11: 4151 | S11: 3516 | T11: 4640 | U11: 4884 | V11: 5128 | W11: 5372 | X11: 5616 | Y11: 5860 | Z11: 6105 | AA11: 6105 | AB11: 6105 | AC11: 6105 | AD11: 6105 | AE11: 0 | AF11: 0 | AG11: 6105 | AH11: 6105 | AI11: 6105 | AJ11: 6105 | AK11: 6105 | AL11: 6105 | AM11: 6105 | AN11: 6105 | AO11: 6105 | AP11: 6105 | AQ11: 0 | AR11: 0 | AS11: 0 | AT11: 0 | AU11: 0 | AV11: 0 | AW11: 0 | AX11: 0 | AY11: 0 | AZ11: 0 | BA11: 0
A12: =IF(B12="","",_xlfn.XLOOKUP(B12&"_"&C12&"_"&D12,[2]ref!$E:$E,[2]ref!$A:$A)) -> Z_FG | B12: Citroen | C12: C4 PIP | D12: SEW | E12: 0 | F12: 0 | G12: 0 | H12: 349 | I12: 262 | J12: 506 | K12: 576 | L12: 645 | M12: 715 | N12: 785 | O12: 855 | P12: 740 | Q12: 795 | R12: 1064 | S12: 907 | T12: 593 | U12: 628 | V12: 663 | W12: 698 | X12: 733 | Y12: 767 | Z12: 802 | AA12: 837 | AB12: 872 | AC12: 872 | AD12: 872 | AE12: 0 | AF12: 0 | AG12: 872 | AH12: 872 | AI12: 872 | AJ12: 872 | AK12: 872 | AL12: 872 | AM12: 872 | AN12: 872 | AO12: 872 | AP12: 872 | AQ12: 0 | AR12: 0 | AS12: 0 | AT12: 0 | AU12: 0 | AV12: 0 | AW12: 0 | AX12: 0 | AY12: 0 | AZ12: 0 | BA12: 0
A13: =IF(B13="","",_xlfn.XLOOKUP(B13&"_"&C13&"_"&D13,[2]ref!$E:$E,[2]ref!$A:$A)) -> G_FG | B13: Nissan | C13: PZ1D | D13: SEW | E13: 380 | F13: 354 | G13: 0 | H13: 0 | I13: 397 | J13: 691 | K13: 720 | L13: 749 | M13: 791 | N13: 832 | O13: 853 | P13: 699 | Q13: 732 | R13: 915 | S13: 732 | T13: 915 | U13: 915 | V13: 915 | W13: 915 | X13: 915 | Y13: 915 | Z13: 915 | AA13: 915 | AB13: 915 | AC13: 0 | AD13: 0 | AE13: 0 | AF13: 0 | AG13: 0 | AH13: 0 | AI13: 0 | AJ13: 0 | AK13: 0 | AL13: 0 | AM13: 0 | AN13: 0 | AO13: 0 | AP13: 832 | AQ13: 832 | AR13: 832 | AS13: 832 | AT13: 832 | AU13: 832 | AV13: 832 | AW13: 832 | AX13: 832 | AY13: 832 | AZ13: 832 | BA13: 872
A14: =IF(B14="","",_xlfn.XLOOKUP(B14&"_"&C14&"_"&D14,[2]ref!$E:$E,[2]ref!$A:$A)) -> U_FG | B14: CV | C14: MAN | D14: SEW | E14: 2678 | F14: 2901 | G14: 2678 | H14: 2678 | I14: 1607 | J14: 2678 | K14: 2678 | L14: 2678 | M14: 2678 | N14: 2678 | O14: 2678 | P14: 2142 | Q14: 2142 | R14: 2678 | S14: 2142 | T14: 2916 | U14: 3043 | V14: 3043 | W14: 3043 | X14: 3043 | Y14: 3043 | Z14: 3043 | AA14: 3043 | AB14: 3043 | AC14: 3043 | AD14: 3043 | AE14: 3043 | AF14: 3043 | AG14: 0 | AH14: 0 | AI14: 3043 | AJ14: 2922 | AK14: 2922 | AL14: 2922 | AM14: 2922 | AN14: 2922 | AO14: 2800 | AP14: 2901 | AQ14: 15087 | AR14: 15087 | AS14: 15087 | AT14: 15087 | AU14: 15087 | AV14: 15087 | AW14: 15087 | AX14: 15087 | AY14: 15087 | AZ14: 15087 | BA14: 15087
... A63: =IF(B63="","",_xlfn.XLOOKUP(B63&"_"&C63&"_"&D63,[2]ref!$E:$E,[2]ref!$A:$A)) -> J_FG | B63: JLR | C63: EMA | D63: SEW | E63: 0 | F63: 0 | G63: 0 | H63: 0 | I63: 0 | J63: 0 | K63: 0 | L63: 161 | M63: 161 | N63: 344 | O63: 367 | P63: 312 | Q63: 331 | R63: 436 | S63: 367 | T63: 918 | U63: 918 | V63: 918 | W63: 918 | X63: 918 | Y63: 918 | Z63: 918 | AA63: 918 | AB63: 918 | AC63: 918 | AD63: 918 | AE63: 0 | AF63: 0 | AG63: 918 | AH63: 918 | AI63: 918 | AJ63: 918 | AK63: 918 | AL63: 918 | AM63: 918 | AN63: 918 | AO63: 918 | AP63: 827 | AQ63: 496 | AR63: 496 | AS63: 496 | AT63: 496 | AU63: 496 | AV63: 496 | AW63: 496 | AX63: 496 | AY63: 496 | AZ63: 496 | BA63: 496
A64: =IF(B64="","",_xlfn.XLOOKUP(B64,[2]ref!$B:$B,[2]ref!$A:$A))

Sheet LTP_Aggregated
A1: {=_xlfn.UNIQUE(_xlfn._xlws.FILTER(LTP_Formulas!A:A,LTP_Formulas!A:A<>""))} -> Prod Line | B1: {=[1]PLANING!$Z63:$BV$63} -> 46041 | C1: 46048 | D1: 46055 | E1: 46062 | F1: 46069 | G1: 46076 | H1: 46083 | I1: 46090 | J1: 46097 | K1: 46104 | L1: 46111 | M1: 46118 | N1: 46125 | O1: 46132 | P1: 46139 | Q1: 46146 | R1: 46153 | S1: 46160 | T1: 46167 | U1: 46174 | V1: 46181 | W1: 46188 | X1: 46195 | Y1: 46202 | Z1: 46209 | AA1: 46216 | AB1: 46223 | AC1: 46230 | AD1: 46237 | AE1: 46244 | AF1: 46251 | AG1: 46258 | AH1: 46265 | AI1: 46272 | AJ1: 46279 | AK1: 46286 | AL1: 46293 | AM1: 46300 | AN1: 46307 | AO1: 46314 | AP1: 46321 | AQ1: 46328 | AR1: 46335 | AS1: 46342 | AT1: 46349 | AU1: 46356 | AV1: 46363 | AW1: 46370 | AX1: 46377
A2: B_FG | B2: {=SUM(_xlfn._xlws.FILTER(LTP_Formulas!E:E,LTP_Formulas!$A:$A=LTP_Aggregated!A2,0))} -> 3298 | C2: {=SUM(_xlfn._xlws.FILTER(LTP_Formulas!F:F,LTP_Formulas!$A:$A=LTP_Aggregated!B2,0))} -> 0 | D2: {=SUM(_xlfn._xlws.FILTER(LTP_Formulas!G:G,LTP_Formulas!$A:$A=LTP_Aggregated!C2,0))} -> 0 | E2: {=SUM(_xlfn._xlws.FILTER(LTP_Formulas!H:H,LTP_Formulas!$A:$A=LTP_Aggregated!D2,0))} -> 0 | F2: {=SUM(_xlfn._xlws.FILTER(LTP_Formulas!I:I,LTP_Formulas!$A:$A=LTP_Aggregated!E2,0))} -> 0 | G2: {=SUM(_xlfn._xlws.FILTER(LTP_Formulas!J:J,LTP_Formulas!$A:$A=LTP_Aggregated!F2,0))} -> 0 | H2: {=SUM(_xlfn._xlws.FILTER(LTP_Formulas!K:K,LTP_Formulas!$A:$A=LTP_Aggregated!G2,0))} -> 0 | I2: {=SUM(_xlfn._xlws.FILTER(LTP_Formulas!L:L,LTP_Formulas!$A:$A=LTP_Aggregated!H2,0))} -> 0 | J2: {=SUM(_xlfn._xlws.FILTER(LTP_Formulas!M:M,LTP_Formulas!$A:$A=LTP_Aggregated!I2,0))} -> 0 | K2: {=SUM(_xlfn._xlws.FILTER(LTP_Formulas!N:N,LTP_Formulas!$A:$A=LTP_Aggregated!J2,0))} -> 0 | L2: {=SUM(_xlfn._xlws.FILTER(LTP_Formulas!O:O,LTP_Formulas!$A:$A=LTP_Aggregated!K2,0))} -> 0 | M2: {=SUM(_xlfn._xlws.FILTER(LTP_Formulas!P:P,LTP_Formulas!$A:$A=LTP_Aggregated!L2,0))} -> 0 | N2: {=SUM(_xlfn._xlws.FILTER(LTP_Formulas!Q:Q,LTP_Formulas!$A:$A=LTP_Aggregated!M2,0))} -> 0 | O2: {=SUM(_xlfn._xlws.FILTER(LTP_Formulas!R:R,LTP_Formulas!$A:$A=LTP_Aggregated!N2,0))} -> 0 | P2: {=SUM(_xlfn._xlws.FILTER(LTP_Formulas!S:S,LTP_Formulas!$A:$A=LTP_Aggregated!O2,0))} -> 0 | Q2: {=SUM(_xlfn._xlws.FILTER(LTP_Formulas!T:T,LTP_Formulas!$A:$A=LTP_Aggregated!P2,0))} -> 0 | R2: {=SUM(_xlfn._xlws.FILTER(LTP_Formulas!U:U,LTP_Formulas!$A:$A=LTP_Aggregated!Q2,0))} -> 0 | S2: {=SUM(_xlfn._xlws.FILTER(LTP_Formulas!V:V,LTP_Formulas!$A:$A=LTP_Aggregated!R2,0))} -> 0 | T2: {=SUM(_xlfn._xlws.FILTER(LTP_Formulas!W:W,LTP_Formulas!$A:$A=LTP_Aggregated!S2,0))} -> 0 | U2: {=SUM(_xlfn._xlws.FILTER(LTP_Formulas!X:X,LTP_Formulas!$A:$A=LTP_Aggregated!T2,0))} -> 0 | V2: {=SUM(_xlfn._xlws.FILTER(LTP_Formulas!Y:Y,LTP_Formulas!$A:$A=LTP_Aggregated!U2,0))} -> 0 | W2: {=SUM(_xlfn._xlws.FILTER(LTP_Formulas!Z:Z,LTP_Formulas!$A:$A=LTP_Aggregated!V2,0))} -> 0 | X2: {=SUM(_xlfn._xlws.FILTER(LTP_Formulas!AA:AA,LTP_Formulas!$A:$A=LTP_Aggregated!W2,0))} -> 0 | Y2: {=SUM(_xlfn._xlws.FILTER(LTP_Formulas!AB:AB,LTP_Formulas!$A:$A=LTP_Aggregated!X2,0))} -> 0 | Z2: {=SUM(_xlfn._xlws.FILTER(LTP_Formulas!AC:AC,LTP_Formulas!$A:$A=LTP_Aggregated!Y2,0))} -> 0 | AA2: {=SUM(_xlfn._xlws.FILTER(LTP_Formulas!AD:AD,LTP_Formulas!$A:$A=LTP_Aggregated!Z2,0))} -> 0 | AB2: {=SUM(_xlfn._xlws.FILTER(LTP_Formulas!AE:AE,LTP_Formulas!$A:$A=LTP_Aggregated!AA2,0))} -> 0 | AC2: {=SUM(_xlfn._xlws.FILTER(LTP_Formulas!AF:AF,LTP_Formulas!$A:$A=LTP_Aggregated!AB2,0))} -> 0 | AD2: {=SUM(_xlfn._xlws.FILTER(LTP_Formulas!AG:AG,LTP_Formulas!$A:$A=LTP_Aggregated!AC2,0))} -> 0 | AE2: {=SUM(_xlfn._xlws.FILTER(LTP_Formulas!AH:AH,LTP_Formulas!$A:$A=LTP_Aggregated!AD2,0))} -> 0 | AF2: {=SUM(_xlfn._xlws.FILTER(LTP_Formulas!AI:AI,LTP_Formulas!$A:$A=LTP_Aggregated!AE2,0))} -> 0 | AG2: {=SUM(_xlfn._xlws.FILTER(LTP_Formulas!AJ:AJ,LTP_Formulas!$A:$A=LTP_Aggregated!AF2,0))} -> 0 | AH2: {=SUM(_xlfn._xlws.FILTER(LTP_Formulas!AK:AK,LTP_Formulas!$A:$A=LTP_Aggregated!AG2,0))} -> 0 | AI2: {=SUM(_xlfn._xlws.FILTER(LTP_Formulas!AL:AL,LTP_Formulas!$A:$A=LTP_Aggregated!AH2,0))} -> 0 | AJ2: {=SUM(_xlfn._xlws.FILTER(LTP_Formulas!AM:AM,LTP_Formulas!$A:$A=LTP_Aggregated!AI2,0))} -> 0 | AK2: {=SUM(_xlfn._xlws.FILTER(LTP_Formulas!AN:AN,LTP_Formulas!$A:$A=LTP_Aggregated!AJ2,0))} -> 0 | AL2: {=SUM(_xlfn._xlws.FILTER(LTP_Formulas!AO:AO,LTP_Formulas!$A:$A=LTP_Aggregated!AK2,0))} -> 0 | AM2: {=SUM(_xlfn._xlws.FILTER(LTP_Formulas!AP:AP,LTP_Formulas!$A:$A=LTP_Aggregated!AL2,0))} -> 0 | AN2: {=SUM(_xlfn._xlws.FILTER(LTP_Formulas!AQ:AQ,LTP_Formulas!$A:$A=LTP_Aggregated!AM2,0))} -> 0 | AO2: {=SUM(_xlfn._xlws.FILTER(LTP_Formulas!AR:AR,LTP_Formulas!$A:$A=LTP_Aggregated!AN2,0))} -> 0 | AP2: {=SUM(_xlfn._xlws.FILTER(LTP_Formulas!AS:AS,LTP_Formulas!$A:$A=LTP_Aggregated!AO2,0))} -> 0 | AQ2: {=SUM(_xlfn._xlws.FILTER(LTP_Formulas!AT:AT,LTP_Formulas!$A:$A=LTP_Aggregated!AP2,0))} -> 0 | AR2: {=SUM(_xlfn._xlws.FILTER(LTP_Formulas!AU:AU,LTP_Formulas!$A:$A=LTP_Aggregated!AQ2,0))} -> 0 | AS2: {=SUM(_xlfn._xlws.FILTER(LTP_Formulas!AV:AV,LTP_Formulas!$A:$A=LTP_Aggregated!AR2,0))} -> 0 | AT2: {=SUM(_xlfn._xlws.FILTER(LTP_Formulas!AW:AW,LTP_Formulas!$A:$A=LTP_Aggregated!AS2,0))} -> 0 | AU2: {=SUM(_xlfn._xlws.FILTER(LTP_Formulas!AX:AX,LTP_Formulas!$A:$A=LTP_Aggregated!AT2,0))} -> 0 | AV2: {=SUM(_xlfn._xlws.FILTER(LTP_Formulas!AY:AY,LTP_Formulas!$A:$A=LTP_Aggregated!AU2,0))} -> 0 | AW2: {=SUM(_xlfn._xlws.FILTER(LTP_Formulas!AZ:AZ,LTP_Formulas!$A:$A=LTP_Aggregated!AV2,0))} -> 0 | AX2: {=SUM(_xlfn._xlws.FILTER(LTP_Formulas!BA:BA,LTP_Formulas!$A:$A=LTP_Aggregated!AW2,0))} -> 0
A3: F_FG | B3: {=SUM(_xlfn._xlws.FILTER(LTP_Formulas!E:E,LTP_Formulas!$A:$A=LTP_Aggregated!A3,0))} -> 5524 | C3: {=SUM(_xlfn._xlws.FILTER(LTP_Formulas!F:F,LTP_Formulas!$A:$A=LTP_Aggregated!B3,0))} -> 0 | D3: {=SUM(_xlfn._xlws.FILTER(LTP_Formulas!G:G,LTP_Formulas!$A:$A=LTP_Aggregated!C3,0))} -> 0 | E3: {=SUM(_xlfn._xlws.FILTER(LTP_Formulas!H:H,LTP_Formulas!$A:$A=LTP_Aggregated!D3,0))} -> 0 | F3: {=SUM(_xlfn._xlws.FILTER(LTP_Formulas!I:I,LTP_Formulas!$A:$A=LTP_Aggregated!E3,0))} -> 0 | G3: {=SUM(_xlfn._xlws.FILTER(LTP_Formulas!J:J,LTP_Formulas!$A:$A=LTP_Aggregated!F3,0))} -> 0 | H3: {=SUM(_xlfn._xlws.FILTER(LTP_Formulas!K:K,LTP_Formulas!$A:$A=LTP_Aggregated!G3,0))} -> 0 | I3: {=SUM(_xlfn._xlws.FILTER(LTP_Formulas!L:L,LTP_Formulas!$A:$A=LTP_Aggregated!H3,0))} -> 0 | J3: {=SUM(_xlfn._xlws.FILTER(LTP_Formulas!M:M,LTP_Formulas!$A:$A=LTP_Aggregated!I3,0))} -> 0 | K3: {=SUM(_xlfn._xlws.FILTER(LTP_Formulas!N:N,LTP_Formulas!$A:$A=LTP_Aggregated!J3,0))} -> 0 | L3: {=SUM(_xlfn._xlws.FILTER(LTP_Formulas!O:O,LTP_Formulas!$A:$A=LTP_Aggregated!K3,0))} -> 0 | M3: {=SUM(_xlfn._xlws.FILTER(LTP_Formulas!P:P,LTP_Formulas!$A:$A=LTP_Aggregated!L3,0))} -> 0 | N3: {=SUM(_xlfn._xlws.FILTER(LTP_Formulas!Q:Q,LTP_Formulas!$A:$A=LTP_Aggregated!M3,0))} -> 0 | O3: {=SUM(_xlfn._xlws.FILTER(LTP_Formulas!R:R,LTP_Formulas!$A:$A=LTP_Aggregated!N3,0))} -> 0 | P3: {=SUM(_xlfn._xlws.FILTER(LTP_Formulas!S:S,LTP_Formulas!$A:$A=LTP_Aggregated!O3,0))} -> 0 | Q3: {=SUM(_xlfn._xlws.FILTER(LTP_Formulas!T:T,LTP_Formulas!$A:$A=LTP_Aggregated!P3,0))} -> 0 | R3: {=SUM(_xlfn._xlws.FILTER(LTP_Formulas!U:U,LTP_Formulas!$A:$A=LTP_Aggregated!Q3,0))} -> 0 | S3: {=SUM(_xlfn._xlws.FILTER(LTP_Formulas!V:V,LTP_Formulas!$A:$A=LTP_Aggregated!R3,0))} -> 0 | T3: {=SUM(_xlfn._xlws.FILTER(LTP_Formulas!W:W,LTP_Formulas!$A:$A=LTP_Aggregated!S3,0))} -> 0 | U3: {=SUM(_xlfn._xlws.FILTER(LTP_Formulas!X:X,LTP_Formulas!$A:$A=LTP_Aggregated!T3,0))} -> 0 | V3: {=SUM(_xlfn._xlws.FILTER(LTP_Formulas!Y:Y,LTP_Formulas!$A:$A=LTP_Aggregated!U3,0))} -> 0 | W3: {=SUM(_xlfn._xlws.FILTER(LTP_Formulas!Z:Z,LTP_Formulas!$A:$A=LTP_Aggregated!V3,0))} -> 0 | X3: {=SUM(_xlfn._xlws.FILTER(LTP_Formulas!AA:AA,LTP_Formulas!$A:$A=LTP_Aggregated!W3,0))} -> 0 | Y3: {=SUM(_xlfn._xlws.FILTER(LTP_Formulas!AB:AB,LTP_Formulas!$A:$A=LTP_Aggregated!X3,0))} -> 0 | Z3: {=SUM(_xlfn._xlws.FILTER(LTP_Formulas!AC:AC,LTP_Formulas!$A:$A=LTP_Aggregated!Y3,0))} -> 0 | AA3: {=SUM(_xlfn._xlws.FILTER(LTP_Formulas!AD:AD,LTP_Formulas!$A:$A=LTP_Aggregated!Z3,0))} -> 0 | AB3: {=SUM(_xlfn._xlws.FILTER(LTP_Formulas!AE:AE,LTP_Formulas!$A:$A=LTP_Aggregated!AA3,0))} -> 0 | AC3: {=SUM(_xlfn._xlws.FILTER(LTP_Formulas!AF:AF,LTP_Formulas!$A:$A=LTP_Aggregated!AB3,0))} -> 0 | AD3: {=SUM(_xlfn._xlws.FILTER(LTP_Formulas!AG:AG,LTP_Formulas!$A:$A=LTP_Aggregated!AC3,0))} -> 0 | AE3: {=SUM(_xlfn._xlws.FILTER(LTP_Formulas!AH:AH,LTP_Formulas!$A:$A=LTP_Aggregated!AD3,0))} -> 0 | AF3: {=SUM(_xlfn._xlws.FILTER(LTP_Formulas!AI:AI,LTP_Formulas!$A:$A=LTP_Aggregated!AE3,0))} -> 0 | AG3: {=SUM(_xlfn._xlws.FILTER(LTP_Formulas!AJ:AJ,LTP_Formulas!$A:$A=LTP_Aggregated!AF3,0))} -> 0 | AH3: {=SUM(_xlfn._xlws.FILTER(LTP_Formulas!AK:AK,LTP_Formulas!$A:$A=LTP_Aggregated!AG3,0))} -> 0 | AI3: {=SUM(_xlfn._xlws.FILTER(LTP_Formulas!AL:AL,LTP_Formulas!$A:$A=LTP_Aggregated!AH3,0))} -> 0 | AJ3: {=SUM(_xlfn._xlws.FILTER(LTP_Formulas!AM:AM,LTP_Formulas!$A:$A=LTP_Aggregated!AI3,0))} -> 0 | AK3: {=SUM(_xlfn._xlws.FILTER(LTP_Formulas!AN:AN,LTP_Formulas!$A:$A=LTP_Aggregated!AJ3,0))} -> 0 | AL3: {=SUM(_xlfn._xlws.FILTER(LTP_Formulas!AO:AO,LTP_Formulas!$A:$A=LTP_Aggregated!AK3,0))} -> 0 | AM3: {=SUM(_xlfn._xlws.FILTER(LTP_Formulas!AP:AP,LTP_Formulas!$A:$A=LTP_Aggregated!AL3,0))} -> 0 | AN3: {=SUM(_xlfn._xlws.FILTER(LTP_Formulas!AQ:AQ,LTP_Formulas!$A:$A=LTP_Aggregated!AM3,0))} -> 0 | AO3: {=SUM(_xlfn._xlws.FILTER(LTP_Formulas!AR:AR,LTP_Formulas!$A:$A=LTP_Aggregated!AN3,0))} -> 0 | AP3: {=SUM(_xlfn._xlws.FILTER(LTP_Formulas!AS:AS,LTP_Formulas!$A:$A=LTP_Aggregated!AO3,0))} -> 0 | AQ3: {=SUM(_xlfn._xlws.FILTER(LTP_Formulas!AT:AT,LTP_Formulas!$A:$A=LTP_Aggregated!AP3,0))} -> 0 | AR3: {=SUM(_xlfn._xlws.FILTER(LTP_Formulas!AU:AU,LTP_Formulas!$A:$A=LTP_Aggregated!AQ3,0))} -> 0 | AS3: {=SUM(_xlfn._xlws.FILTER(LTP_Formulas!AV:AV,LTP_Formulas!$A:$A=LTP_Aggregated!AR3,0))} -> 0 | AT3: {=SUM(_xlfn._xlws.FILTER(LTP_Formulas!AW:AW,LTP_Formulas!$A:$A=LTP_Aggregated!AS3,0))} -> 0 | AU3: {=SUM(_xlfn._xlws.FILTER(LTP_Formulas!AX:AX,LTP_Formulas!$A:$A=LTP_Aggregated!AT3,0))} -> 0 | AV3: {=SUM(_xlfn._xlws.FILTER(LTP_Formulas!AY:AY,LTP_Formulas!$A:$A=LTP_Aggregated!AU3,0))} -> 0 | AW3: {=SUM(_xlfn._xlws.FILTER(LTP_Formulas!AZ:AZ,LTP_Formulas!$A:$A=LTP_Aggregated!AV3,0))} -> 0 | AX3: {=SUM(_xlfn._xlws.FILTER(LTP_Formulas!BA:BA,LTP_Formulas!$A:$A=LTP_Aggregated!AW3,0))} -> 0
A4: P_FG | B4: {=SUM(_xlfn._xlws.FILTER(LTP_Formulas!E:E,LTP_Formulas!$A:$A=LTP_Aggregated!A4,0))} -> 2478 | C4: {=SUM(_xlfn._xlws.FILTER(LTP_Formulas!F:F,LTP_Formulas!$A:$A=LTP_Aggregated!B4,0))} -> 0 | D4: {=SUM(_xlfn._xlws.FILTER(LTP_Formulas!G:G,LTP_Formulas!$A:$A=LTP_Aggregated!C4,0))} -> 0 | E4: {=SUM(_xlfn._xlws.FILTER(LTP_Formulas!H:H,LTP_Formulas!$A:$A=LTP_Aggregated!D4,0))} -> 0 | F4: {=SUM(_xlfn._xlws.FILTER(LTP_Formulas!I:I,LTP_Formulas!$A:$A=LTP_Aggregated!E4,0))} -> 0 | G4: {=SUM(_xlfn._xlws.FILTER(LTP_Formulas!J:J,LTP_Formulas!$A:$A=LTP_Aggregated!F4,0))} -> 0 | H4: {=SUM(_xlfn._xlws.FILTER(LTP_Formulas!K:K,LTP_Formulas!$A:$A=LTP_Aggregated!G4,0))} -> 0 | I4: {=SUM(_xlfn._xlws.FILTER(LTP_Formulas!L:L,LTP_Formulas!$A:$A=LTP_Aggregated!H4,0))} -> 0 | J4: {=SUM(_xlfn._xlws.FILTER(LTP_Formulas!M:M,LTP_Formulas!$A:$A=LTP_Aggregated!I4,0))} -> 0 | K4: {=SUM(_xlfn._xlws.FILTER(LTP_Formulas!N:N,LTP_Formulas!$A:$A=LTP_Aggregated!J4,0))} -> 0 | L4: {=SUM(_xlfn._xlws.FILTER(LTP_Formulas!O:O,LTP_Formulas!$A:$A=LTP_Aggregated!K4,0))} -> 0 | M4: {=SUM(_xlfn._xlws.FILTER(LTP_Formulas!P:P,LTP_Formulas!$A:$A=LTP_Aggregated!L4,0))} -> 0 | N4: {=SUM(_xlfn._xlws.FILTER(LTP_Formulas!Q:Q,LTP_Formulas!$A:$A=LTP_Aggregated!M4,0))} -> 0 | O4: {=SUM(_xlfn._xlws.FILTER(LTP_Formulas!R:R,LTP_Formulas!$A:$A=LTP_Aggregated!N4,0))} -> 0 | P4: {=SUM(_xlfn._xlws.FILTER(LTP_Formulas!S:S,LTP_Formulas!$A:$A=LTP_Aggregated!O4,0))} -> 0 | Q4: {=SUM(_xlfn._xlws.FILTER(LTP_Formulas!T:T,LTP_Formulas!$A:$A=LTP_Aggregated!P4,0))} -> 0 | R4: {=SUM(_xlfn._xlws.FILTER(LTP_Formulas!U:U,LTP_Formulas!$A:$A=LTP_Aggregated!Q4,0))} -> 0 | S4: {=SUM(_xlfn._xlws.FILTER(LTP_Formulas!V:V,LTP_Formulas!$A:$A=LTP_Aggregated!R4,0))} -> 0 | T4: {=SUM(_xlfn._xlws.FILTER(LTP_Formulas!W:W,LTP_Formulas!$A:$A=LTP_Aggregated!S4,0))} -> 0 | U4: {=SUM(_xlfn._xlws.FILTER(LTP_Formulas!X:X,LTP_Formulas!$A:$A=LTP_Aggregated!T4,0))} -> 0 | V4: {=SUM(_xlfn._xlws.FILTER(LTP_Formulas!Y:Y,LTP_Formulas!$A:$A=LTP_Aggregated!U4,0))} -> 0 | W4: {=SUM(_xlfn._xlws.FILTER(LTP_Formulas!Z:Z,LTP_Formulas!$A:$A=LTP_Aggregated!V4,0))} -> 0 | X4: {=SUM(_xlfn._xlws.FILTER(LTP_Formulas!AA:AA,LTP_Formulas!$A:$A=LTP_Aggregated!W4,0))} -> 0 | Y4: {=SUM(_xlfn._xlws.FILTER(LTP_Formulas!AB:AB,LTP_Formulas!$A:$A=LTP_Aggregated!X4,0))} -> 0 | Z4: {=SUM(_xlfn._xlws.FILTER(LTP_Formulas!AC:AC,LTP_Formulas!$A:$A=LTP_Aggregated!Y4,0))} -> 0 | AA4: {=SUM(_xlfn._xlws.FILTER(LTP_Formulas!AD:AD,LTP_Formulas!$A:$A=LTP_Aggregated!Z4,0))} -> 0 | AB4: {=SUM(_xlfn._xlws.FILTER(LTP_Formulas!AE:AE,LTP_Formulas!$A:$A=LTP_Aggregated!AA4,0))} -> 0 | AC4: {=SUM(_xlfn._xlws.FILTER(LTP_Formulas!AF:AF,LTP_Formulas!$A:$A=LTP_Aggregated!AB4,0))} -> 0 | AD4: {=SUM(_xlfn._xlws.FILTER(LTP_Formulas!AG:AG,LTP_Formulas!$A:$A=LTP_Aggregated!AC4,0))} -> 0 | AE4: {=SUM(_xlfn._xlws.FILTER(LTP_Formulas!AH:AH,LTP_Formulas!$A:$A=LTP_Aggregated!AD4,0))} -> 0 | AF4: {=SUM(_xlfn._xlws.FILTER(LTP_Formulas!AI:AI,LTP_Formulas!$A:$A=LTP_Aggregated!AE4,0))} -> 0 | AG4: {=SUM(_xlfn._xlws.FILTER(LTP_Formulas!AJ:AJ,LTP_Formulas!$A:$A=LTP_Aggregated!AF4,0))} -> 0 | AH4: {=SUM(_xlfn._xlws.FILTER(LTP_Formulas!AK:AK,LTP_Formulas!$A:$A=LTP_Aggregated!AG4,0))} -> 0 | AI4: {=SUM(_xlfn._xlws.FILTER(LTP_Formulas!AL:AL,LTP_Formulas!$A:$A=LTP_Aggregated!AH4,0))} -> 0 | AJ4: {=SUM(_xlfn._xlws.FILTER(LTP_Formulas!AM:AM,LTP_Formulas!$A:$A=LTP_Aggregated!AI4,0))} -> 0 | AK4: {=SUM(_xlfn._xlws.FILTER(LTP_Formulas!AN:AN,LTP_Formulas!$A:$A=LTP_Aggregated!AJ4,0))} -> 0 | AL4: {=SUM(_xlfn._xlws.FILTER(LTP_Formulas!AO:AO,LTP_Formulas!$A:$A=LTP_Aggregated!AK4,0))} -> 0 | AM4: {=SUM(_xlfn._xlws.FILTER(LTP_Formulas!AP:AP,LTP_Formulas!$A:$A=LTP_Aggregated!AL4,0))} -> 0 | AN4: {=SUM(_xlfn._xlws.FILTER(LTP_Formulas!AQ:AQ,LTP_Formulas!$A:$A=LTP_Aggregated!AM4,0))} -> 0 | AO4: {=SUM(_xlfn._xlws.FILTER(LTP_Formulas!AR:AR,LTP_Formulas!$A:$A=LTP_Aggregated!AN4,0))} -> 0 | AP4: {=SUM(_xlfn._xlws.FILTER(LTP_Formulas!AS:AS,LTP_Formulas!$A:$A=LTP_Aggregated!AO4,0))} -> 0 | AQ4: {=SUM(_xlfn._xlws.FILTER(LTP_Formulas!AT:AT,LTP_Formulas!$A:$A=LTP_Aggregated!AP4,0))} -> 0 | AR4: {=SUM(_xlfn._xlws.FILTER(LTP_Formulas!AU:AU,LTP_Formulas!$A:$A=LTP_Aggregated!AQ4,0))} -> 0 | AS4: {=SUM(_xlfn._xlws.FILTER(LTP_Formulas!AV:AV,LTP_Formulas!$A:$A=LTP_Aggregated!AR4,0))} -> 0 | AT4: {=SUM(_xlfn._xlws.FILTER(LTP_Formulas!AW:AW,LTP_Formulas!$A:$A=LTP_Aggregated!AS4,0))} -> 0 | AU4: {=SUM(_xlfn._xlws.FILTER(LTP_Formulas!AX:AX,LTP_Formulas!$A:$A=LTP_Aggregated!AT4,0))} -> 0 | AV4: {=SUM(_xlfn._xlws.FILTER(LTP_Formulas!AY:AY,LTP_Formulas!$A:$A=LTP_Aggregated!AU4,0))} -> 0 | AW4: {=SUM(_xlfn._xlws.FILTER(LTP_Formulas!AZ:AZ,LTP_Formulas!$A:$A=LTP_Aggregated!AV4,0))} -> 0 | AX4: {=SUM(_xlfn._xlws.FILTER(LTP_Formulas!BA:BA,LTP_Formulas!$A:$A=LTP_Aggregated!AW4,0))} -> 0
A5: V_FG | B5: {=SUM(_xlfn._xlws.FILTER(LTP_Formulas!E:E,LTP_Formulas!$A:$A=LTP_Aggregated!A5,0))} -> 20490 | C5: {=SUM(_xlfn._xlws.FILTER(LTP_Formulas!F:F,LTP_Formulas!$A:$A=LTP_Aggregated!B5,0))} -> 0 | D5: {=SUM(_xlfn._xlws.FILTER(LTP_Formulas!G:G,LTP_Formulas!$A:$A=LTP_Aggregated!C5,0))} -> 0 | E5: {=SUM(_xlfn._xlws.FILTER(LTP_Formulas!H:H,LTP_Formulas!$A:$A=LTP_Aggregated!D5,0))} -> 0 | F5: {=SUM(_xlfn._xlws.FILTER(LTP_Formulas!I:I,LTP_Formulas!$A:$A=LTP_Aggregated!E5,0))} -> 0 | G5: {=SUM(_xlfn._xlws.FILTER(LTP_Formulas!J:J,LTP_Formulas!$A:$A=LTP_Aggregated!F5,0))} -> 0 | H5: {=SUM(_xlfn._xlws.FILTER(LTP_Formulas!K:K,LTP_Formulas!$A:$A=LTP_Aggregated!G5,0))} -> 0 | I5: {=SUM(_xlfn._xlws.FILTER(LTP_Formulas!L:L,LTP_Formulas!$A:$A=LTP_Aggregated!H5,0))} -> 0 | J5: {=SUM(_xlfn._xlws.FILTER(LTP_Formulas!M:M,LTP_Formulas!$A:$A=LTP_Aggregated!I5,0))} -> 0 | K5: {=SUM(_xlfn._xlws.FILTER(LTP_Formulas!N:N,LTP_Formulas!$A:$A=LTP_Aggregated!J5,0))} -> 0 | L5: {=SUM(_xlfn._xlws.FILTER(LTP_Formulas!O:O,LTP_Formulas!$A:$A=LTP_Aggregated!K5,0))} -> 0 | M5: {=SUM(_xlfn._xlws.FILTER(LTP_Formulas!P:P,LTP_Formulas!$A:$A=LTP_Aggregated!L5,0))} -> 0 | N5: {=SUM(_xlfn._xlws.FILTER(LTP_Formulas!Q:Q,LTP_Formulas!$A:$A=LTP_Aggregated!M5,0))} -> 0 | O5: {=SUM(_xlfn._xlws.FILTER(LTP_Formulas!R:R,LTP_Formulas!$A:$A=LTP_Aggregated!N5,0))} -> 0 | P5: {=SUM(_xlfn._xlws.FILTER(LTP_Formulas!S:S,LTP_Formulas!$A:$A=LTP_Aggregated!O5,0))} -> 0 | Q5: {=SUM(_xlfn._xlws.FILTER(LTP_Formulas!T:T,LTP_Formulas!$A:$A=LTP_Aggregated!P5,0))} -> 0 | R5: {=SUM(_xlfn._xlws.FILTER(LTP_Formulas!U:U,LTP_Formulas!$A:$A=LTP_Aggregated!Q5,0))} -> 0 | S5: {=SUM(_xlfn._xlws.FILTER(LTP_Formulas!V:V,LTP_Formulas!$A:$A=LTP_Aggregated!R5,0))} -> 0 | T5: {=SUM(_xlfn._xlws.FILTER(LTP_Formulas!W:W,LTP_Formulas!$A:$A=LTP_Aggregated!S5,0))} -> 0 | U5: {=SUM(_xlfn._xlws.FILTER(LTP_Formulas!X:X,LTP_Formulas!$A:$A=LTP_Aggregated!T5,0))} -> 0 | V5: {=SUM(_xlfn._xlws.FILTER(LTP_Formulas!Y:Y,LTP_Formulas!$A:$A=LTP_Aggregated!U5,0))} -> 0 | W5: {=SUM(_xlfn._xlws.FILTER(LTP_Formulas!Z:Z,LTP_Formulas!$A:$A=LTP_Aggregated!V5,0))} -> 0 | X5: {=SUM(_xlfn._xlws.FILTER(LTP_Formulas!AA:AA,LTP_Formulas!$A:$A=LTP_Aggregated!W5,0))} -> 0 | Y5: {=SUM(_xlfn._xlws.FILTER(LTP_Formulas!AB:AB,LTP_Formulas!$A:$A=LTP_Aggregated!X5,0))} -> 0 | Z5: {=SUM(_xlfn._xlws.FILTER(LTP_Formulas!AC:AC,LTP_Formulas!$A:$A=LTP_Aggregated!Y5,0))} -> 0 | AA5: {=SUM(_xlfn._xlws.FILTER(LTP_Formulas!AD:AD,LTP_Formulas!$A:$A=LTP_Aggregated!Z5,0))} -> 0 | AB5: {=SUM(_xlfn._xlws.FILTER(LTP_Formulas!AE:AE,LTP_Formulas!$A:$A=LTP_Aggregated!AA5,0))} -> 0 | AC5: {=SUM(_xlfn._xlws.FILTER(LTP_Formulas!AF:AF,LTP_Formulas!$A:$A=LTP_Aggregated!AB5,0))} -> 0 | AD5: {=SUM(_xlfn._xlws.FILTER(LTP_Formulas!AG:AG,LTP_Formulas!$A:$A=LTP_Aggregated!AC5,0))} -> 0 | AE5: {=SUM(_xlfn._xlws.FILTER(LTP_Formulas!AH:AH,LTP_Formulas!$A:$A=LTP_Aggregated!AD5,0))} -> 0 | AF5: {=SUM(_xlfn._xlws.FILTER(LTP_Formulas!AI:AI,LTP_Formulas!$A:$A=LTP_Aggregated!AE5,0))} -> 0 | AG5: {=SUM(_xlfn._xlws.FILTER(LTP_Formulas!AJ:AJ,LTP_Formulas!$A:$A=LTP_Aggregated!AF5,0))} -> 0 | AH5: {=SUM(_xlfn._xlws.FILTER(LTP_Formulas!AK:AK,LTP_Formulas!$A:$A=LTP_Aggregated!AG5,0))} -> 0 | AI5: {=SUM(_xlfn._xlws.FILTER(LTP_Formulas!AL:AL,LTP_Formulas!$A:$A=LTP_Aggregated!AH5,0))} -> 0 | AJ5: {=SUM(_xlfn._xlws.FILTER(LTP_Formulas!AM:AM,LTP_Formulas!$A:$A=LTP_Aggregated!AI5,0))} -> 0 | AK5: {=SUM(_xlfn._xlws.FILTER(LTP_Formulas!AN:AN,LTP_Formulas!$A:$A=LTP_Aggregated!AJ5,0))} -> 0 | AL5: {=SUM(_xlfn._xlws.FILTER(LTP_Formulas!AO:AO,LTP_Formulas!$A:$A=LTP_Aggregated!AK5,0))} -> 0 | AM5: {=SUM(_xlfn._xlws.FILTER(LTP_Formulas!AP:AP,LTP_Formulas!$A:$A=LTP_Aggregated!AL5,0))} -> 0 | AN5: {=SUM(_xlfn._xlws.FILTER(LTP_Formulas!AQ:AQ,LTP_Formulas!$A:$A=LTP_Aggregated!AM5,0))} -> 0 | AO5: {=SUM(_xlfn._xlws.FILTER(LTP_Formulas!AR:AR,LTP_Formulas!$A:$A=LTP_Aggregated!AN5,0))} -> 0 | AP5: {=SUM(_xlfn._xlws.FILTER(LTP_Formulas!AS:AS,LTP_Formulas!$A:$A=LTP_Aggregated!AO5,0))} -> 0 | AQ5: {=SUM(_xlfn._xlws.FILTER(LTP_Formulas!AT:AT,LTP_Formulas!$A:$A=LTP_Aggregated!AP5,0))} -> 0 | AR5: {=SUM(_xlfn._xlws.FILTER(LTP_Formulas!AU:AU,LTP_Formulas!$A:$A=LTP_Aggregated!AQ5,0))} -> 0 | AS5: {=SUM(_xlfn._xlws.FILTER(LTP_Formulas!AV:AV,LTP_Formulas!$A:$A=LTP_Aggregated!AR5,0))} -> 0 | AT5: {=SUM(_xlfn._xlws.FILTER(LTP_Formulas!AW:AW,LTP_Formulas!$A:$A=LTP_Aggregated!AS5,0))} -> 0 | AU5: {=SUM(_xlfn._xlws.FILTER(LTP_Formulas!AX:AX,LTP_Formulas!$A:$A=LTP_Aggregated!AT5,0))} -> 0 | AV5: {=SUM(_xlfn._xlws.FILTER(LTP_Formulas!AY:AY,LTP_Formulas!$A:$A=LTP_Aggregated!AU5,0))} -> 0 | AW5: {=SUM(_xlfn._xlws.FILTER(LTP_Formulas!AZ:AZ,LTP_Formulas!$A:$A=LTP_Aggregated!AV5,0))} -> 0 | AX5: {=SUM(_xlfn._xlws.FILTER(LTP_Formulas!BA:BA,LTP_Formulas!$A:$A=LTP_Aggregated!AW5,0))} -> 0
A6: T_FG | B6: {=SUM(_xlfn._xlws.FILTER(LTP_Formulas!E:E,LTP_Formulas!$A:$A=LTP_Aggregated!A6,0))} -> 0 | C6: {=SUM(_xlfn._xlws.FILTER(LTP_Formulas!F:F,LTP_Formulas!$A:$A=LTP_Aggregated!B6,0))} -> 0 | D6: {=SUM(_xlfn._xlws.FILTER(LTP_Formulas!G:G,LTP_Formulas!$A:$A=LTP_Aggregated!C6,0))} -> 0 | E6: {=SUM(_xlfn._xlws.FILTER(LTP_Formulas!H:H,LTP_Formulas!$A:$A=LTP_Aggregated!D6,0))} -> 0 | F6: {=SUM(_xlfn._xlws.FILTER(LTP_Formulas!I:I,LTP_Formulas!$A:$A=LTP_Aggregated!E6,0))} -> 0 | G6: {=SUM(_xlfn._xlws.FILTER(LTP_Formulas!J:J,LTP_Formulas!$A:$A=LTP_Aggregated!F6,0))} -> 0 | H6: {=SUM(_xlfn._xlws.FILTER(LTP_Formulas!K:K,LTP_Formulas!$A:$A=LTP_Aggregated!G6,0))} -> 0 | I6: {=SUM(_xlfn._xlws.FILTER(LTP_Formulas!L:L,LTP_Formulas!$A:$A=LTP_Aggregated!H6,0))} -> 0 | J6: {=SUM(_xlfn._xlws.FILTER(LTP_Formulas!M:M,LTP_Formulas!$A:$A=LTP_Aggregated!I6,0))} -> 0 | K6: {=SUM(_xlfn._xlws.FILTER(LTP_Formulas!N:N,LTP_Formulas!$A:$A=LTP_Aggregated!J6,0))} -> 0 | L6: {=SUM(_xlfn._xlws.FILTER(LTP_Formulas!O:O,LTP_Formulas!$A:$A=LTP_Aggregated!K6,0))} -> 0 | M6: {=SUM(_xlfn._xlws.FILTER(LTP_Formulas!P:P,LTP_Formulas!$A:$A=LTP_Aggregated!L6,0))} -> 0 | N6: {=SUM(_xlfn._xlws.FILTER(LTP_Formulas!Q:Q,LTP_Formulas!$A:$A=LTP_Aggregated!M6,0))} -> 0 | O6: {=SUM(_xlfn._xlws.FILTER(LTP_Formulas!R:R,LTP_Formulas!$A:$A=LTP_Aggregated!N6,0))} -> 0 | P6: {=SUM(_xlfn._xlws.FILTER(LTP_Formulas!S:S,LTP_Formulas!$A:$A=LTP_Aggregated!O6,0))} -> 0 | Q6: {=SUM(_xlfn._xlws.FILTER(LTP_Formulas!T:T,LTP_Formulas!$A:$A=LTP_Aggregated!P6,0))} -> 0 | R6: {=SUM(_xlfn._xlws.FILTER(LTP_Formulas!U:U,LTP_Formulas!$A:$A=LTP_Aggregated!Q6,0))} -> 0 | S6: {=SUM(_xlfn._xlws.FILTER(LTP_Formulas!V:V,LTP_Formulas!$A:$A=LTP_Aggregated!R6,0))} -> 0 | T6: {=SUM(_xlfn._xlws.FILTER(LTP_Formulas!W:W,LTP_Formulas!$A:$A=LTP_Aggregated!S6,0))} -> 0 | U6: {=SUM(_xlfn._xlws.FILTER(LTP_Formulas!X:X,LTP_Formulas!$A:$A=LTP_Aggregated!T6,0))} -> 0 | V6: {=SUM(_xlfn._xlws.FILTER(LTP_Formulas!Y:Y,LTP_Formulas!$A:$A=LTP_Aggregated!U6,0))} -> 0 | W6: {=SUM(_xlfn._xlws.FILTER(LTP_Formulas!Z:Z,LTP_Formulas!$A:$A=LTP_Aggregated!V6,0))} -> 0 | X6: {=SUM(_xlfn._xlws.FILTER(LTP_Formulas!AA:AA,LTP_Formulas!$A:$A=LTP_Aggregated!W6,0))} -> 0 | Y6: {=SUM(_xlfn._xlws.FILTER(LTP_Formulas!AB:AB,LTP_Formulas!$A:$A=LTP_Aggregated!X6,0))} -> 0 | Z6: {=SUM(_xlfn._xlws.FILTER(LTP_Formulas!AC:AC,LTP_Formulas!$A:$A=LTP_Aggregated!Y6,0))} -> 0 | AA6: {=SUM(_xlfn._xlws.FILTER(LTP_Formulas!AD:AD,LTP_Formulas!$A:$A=LTP_Aggregated!Z6,0))} -> 0 | AB6: {=SUM(_xlfn._xlws.FILTER(LTP_Formulas!AE:AE,LTP_Formulas!$A:$A=LTP_Aggregated!AA6,0))} -> 0 | AC6: {=SUM(_xlfn._xlws.FILTER(LTP_Formulas!AF:AF,LTP_Formulas!$A:$A=LTP_Aggregated!AB6,0))} -> 0 | AD6: {=SUM(_xlfn._xlws.FILTER(LTP_Formulas!AG:AG,LTP_Formulas!$A:$A=LTP_Aggregated!AC6,0))} -> 0 | AE6: {=SUM(_xlfn._xlws.FILTER(LTP_Formulas!AH:AH,LTP_Formulas!$A:$A=LTP_Aggregated!AD6,0))} -> 0 | AF6: {=SUM(_xlfn._xlws.FILTER(LTP_Formulas!AI:AI,LTP_Formulas!$A:$A=LTP_Aggregated!AE6,0))} -> 0 | AG6: {=SUM(_xlfn._xlws.FILTER(LTP_Formulas!AJ:AJ,LTP_Formulas!$A:$A=LTP_Aggregated!AF6,0))} -> 0 | AH6: {=SUM(_xlfn._xlws.FILTER(LTP_Formulas!AK:AK,LTP_Formulas!$A:$A=LTP_Aggregated!AG6,0))} -> 0 | AI6: {=SUM(_xlfn._xlws.FILTER(LTP_Formulas!AL:AL,LTP_Formulas!$A:$A=LTP_Aggregated!AH6,0))} -> 0 | AJ6: {=SUM(_xlfn._xlws.FILTER(LTP_Formulas!AM:AM,LTP_Formulas!$A:$A=LTP_Aggregated!AI6,0))} -> 0 | AK6: {=SUM(_xlfn._xlws.FILTER(LTP_Formulas!AN:AN,LTP_Formulas!$A:$A=LTP_Aggregated!AJ6,0))} -> 0 | AL6: {=SUM(_xlfn._xlws.FILTER(LTP_Formulas!AO:AO,LTP_Formulas!$A:$A=LTP_Aggregated!AK6,0))} -> 0 | AM6: {=SUM(_xlfn._xlws.FILTER(LTP_Formulas!AP:AP,LTP_Formulas!$A:$A=LTP_Aggregated!AL6,0))} -> 0 | AN6: {=SUM(_xlfn._xlws.FILTER(LTP_Formulas!AQ:AQ,LTP_Formulas!$A:$A=LTP_Aggregated!AM6,0))} -> 0 | AO6: {=SUM(_xlfn._xlws.FILTER(LTP_Formulas!AR:AR,LTP_Formulas!$A:$A=LTP_Aggregated!AN6,0))} -> 0 | AP6: {=SUM(_xlfn._xlws.FILTER(LTP_Formulas!AS:AS,LTP_Formulas!$A:$A=LTP_Aggregated!AO6,0))} -> 0 | AQ6: {=SUM(_xlfn._xlws.FILTER(LTP_Formulas!AT:AT,LTP_Formulas!$A:$A=LTP_Aggregated!AP6,0))} -> 0 | AR6: {=SUM(_xlfn._xlws.FILTER(LTP_Formulas!AU:AU,LTP_Formulas!$A:$A=LTP_Aggregated!AQ6,0))} -> 0 | AS6: {=SUM(_xlfn._xlws.FILTER(LTP_Formulas!AV:AV,LTP_Formulas!$A:$A=LTP_Aggregated!AR6,0))} -> 0 | AT6: {=SUM(_xlfn._xlws.FILTER(LTP_Formulas!AW:AW,LTP_Formulas!$A:$A=LTP_Aggregated!AS6,0))} -> 0 | AU6: {=SUM(_xlfn._xlws.FILTER(LTP_Formulas!AX:AX,LTP_Formulas!$A:$A=LTP_Aggregated!AT6,0))} -> 0 | AV6: {=SUM(_xlfn._xlws.FILTER(LTP_Formulas!AY:AY,LTP_Formulas!$A:$A=LTP_Aggregated!AU6,0))} -> 0 | AW6: {=SUM(_xlfn._xlws.FILTER(LTP_Formulas!AZ:AZ,LTP_Formulas!$A:$A=LTP_Aggregated!AV6,0))} -> 0 | AX6: {=SUM(_xlfn._xlws.FILTER(LTP_Formulas!BA:BA,LTP_Formulas!$A:$A=LTP_Aggregated!AW6,0))} -> 0
A7: Z_FG | B7: {=SUM(_xlfn._xlws.FILTER(LTP_Formulas!E:E,LTP_Formulas!$A:$A=LTP_Aggregated!A7,0))} -> 4730 | C7: {=SUM(_xlfn._xlws.FILTER(LTP_Formulas!F:F,LTP_Formulas!$A:$A=LTP_Aggregated!B7,0))} -> 0 | D7: {=SUM(_xlfn._xlws.FILTER(LTP_Formulas!G:G,LTP_Formulas!$A:$A=LTP_Aggregated!C7,0))} -> 0 | E7: {=SUM(_xlfn._xlws.FILTER(LTP_Formulas!H:H,LTP_Formulas!$A:$A=LTP_Aggregated!D7,0))} -> 0 | F7: {=SUM(_xlfn._xlws.FILTER(LTP_Formulas!I:I,LTP_Formulas!$A:$A=LTP_Aggregated!E7,0))} -> 0 | G7: {=SUM(_xlfn._xlws.FILTER(LTP_Formulas!J:J,LTP_Formulas!$A:$A=LTP_Aggregated!F7,0))} -> 0 | H7: {=SUM(_xlfn._xlws.FILTER(LTP_Formulas!K:K,LTP_Formulas!$A:$A=LTP_Aggregated!G7,0))} -> 0 | I7: {=SUM(_xlfn._xlws.FILTER(LTP_Formulas!L:L,LTP_Formulas!$A:$A=LTP_Aggregated!H7,0))} -> 0 | J7: {=SUM(_xlfn._xlws.FILTER(LTP_Formulas!M:M,LTP_Formulas!$A:$A=LTP_Aggregated!I7,0))} -> 0 | K7: {=SUM(_xlfn._xlws.FILTER(LTP_Formulas!N:N,LTP_Formulas!$A:$A=LTP_Aggregated!J7,0))} -> 0 | L7: {=SUM(_xlfn._xlws.FILTER(LTP_Formulas!O:O,LTP_Formulas!$A:$A=LTP_Aggregated!K7,0))} -> 0 | M7: {=SUM(_xlfn._xlws.FILTER(LTP_Formulas!P:P,LTP_Formulas!$A:$A=LTP_Aggregated!L7,0))} -> 0 | N7: {=SUM(_xlfn._xlws.FILTER(LTP_Formulas!Q:Q,LTP_Formulas!$A:$A=LTP_Aggregated!M7,0))} -> 0 | O7: {=SUM(_xlfn._xlws.FILTER(LTP_Formulas!R:R,LTP_Formulas!$A:$A=LTP_Aggregated!N7,0))} -> 0 | P7: {=SUM(_xlfn._xlws.FILTER(LTP_Formulas!S:S,LTP_Formulas!$A:$A=LTP_Aggregated!O7,0))} -> 0 | Q7: {=SUM(_xlfn._xlws.FILTER(LTP_Formulas!T:T,LTP_Formulas!$A:$A=LTP_Aggregated!P7,0))} -> 0 | R7: {=SUM(_xlfn._xlws.FILTER(LTP_Formulas!U:U,LTP_Formulas!$A:$A=LTP_Aggregated!Q7,0))} -> 0 | S7: {=SUM(_xlfn._xlws.FILTER(LTP_Formulas!V:V,LTP_Formulas!$A:$A=LTP_Aggregated!R7,0))} -> 0 | T7: {=SUM(_xlfn._xlws.FILTER(LTP_Formulas!W:W,LTP_Formulas!$A:$A=LTP_Aggregated!S7,0))} -> 0 | U7: {=SUM(_xlfn._xlws.FILTER(LTP_Formulas!X:X,LTP_Formulas!$A:$A=LTP_Aggregated!T7,0))} -> 0 | V7: {=SUM(_xlfn._xlws.FILTER(LTP_Formulas!Y:Y,LTP_Formulas!$A:$A=LTP_Aggregated!U7,0))} -> 0 | W7: {=SUM(_xlfn._xlws.FILTER(LTP_Formulas!Z:Z,LTP_Formulas!$A:$A=LTP_Aggregated!V7,0))} -> 0 | X7: {=SUM(_xlfn._xlws.FILTER(LTP_Formulas!AA:AA,LTP_Formulas!$A:$A=LTP_Aggregated!W7,0))} -> 0 | Y7: {=SUM(_xlfn._xlws.FILTER(LTP_Formulas!AB:AB,LTP_Formulas!$A:$A=LTP_Aggregated!X7,0))} -> 0 | Z7: {=SUM(_xlfn._xlws.FILTER(LTP_Formulas!AC:AC,LTP_Formulas!$A:$A=LTP_Aggregated!Y7,0))} -> 0 | AA7: {=SUM(_xlfn._xlws.FILTER(LTP_Formulas!AD:AD,LTP_Formulas!$A:$A=LTP_Aggregated!Z7,0))} -> 0 | AB7: {=SUM(_xlfn._xlws.FILTER(LTP_Formulas!AE:AE,LTP_Formulas!$A:$A=LTP_Aggregated!AA7,0))} -> 0 | AC7: {=SUM(_xlfn._xlws.FILTER(LTP_Formulas!AF:AF,LTP_Formulas!$A:$A=LTP_Aggregated!AB7,0))} -> 0 | AD7: {=SUM(_xlfn._xlws.FILTER(LTP_Formulas!AG:AG,LTP_Formulas!$A:$A=LTP_Aggregated!AC7,0))} -> 0 | AE7: {=SUM(_xlfn._xlws.FILTER(LTP_Formulas!AH:AH,LTP_Formulas!$A:$A=LTP_Aggregated!AD7,0))} -> 0 | AF7: {=SUM(_xlfn._xlws.FILTER(LTP_Formulas!AI:AI,LTP_Formulas!$A:$A=LTP_Aggregated!AE7,0))} -> 0 | AG7: {=SUM(_xlfn._xlws.FILTER(LTP_Formulas!AJ:AJ,LTP_Formulas!$A:$A=LTP_Aggregated!AF7,0))} -> 0 | AH7: {=SUM(_xlfn._xlws.FILTER(LTP_Formulas!AK:AK,LTP_Formulas!$A:$A=LTP_Aggregated!AG7,0))} -> 0 | AI7: {=SUM(_xlfn._xlws.FILTER(LTP_Formulas!AL:AL,LTP_Formulas!$A:$A=LTP_Aggregated!AH7,0))} -> 0 | AJ7: {=SUM(_xlfn._xlws.FILTER(LTP_Formulas!AM:AM,LTP_Formulas!$A:$A=LTP_Aggregated!AI7,0))} -> 0 | AK7: {=SUM(_xlfn._xlws.FILTER(LTP_Formulas!AN:AN,LTP_Formulas!$A:$A=LTP_Aggregated!AJ7,0))} -> 0 | AL7: {=SUM(_xlfn._xlws.FILTER(LTP_Formulas!AO:AO,LTP_Formulas!$A:$A=LTP_Aggregated!AK7,0))} -> 0 | AM7: {=SUM(_xlfn._xlws.FILTER(LTP_Formulas!AP:AP,LTP_Formulas!$A:$A=LTP_Aggregated!AL7,0))} -> 0 | AN7: {=SUM(_xlfn._xlws.FILTER(LTP_Formulas!AQ:AQ,LTP_Formulas!$A:$A=LTP_Aggregated!AM7,0))} -> 0 | AO7: {=SUM(_xlfn._xlws.FILTER(LTP_Formulas!AR:AR,LTP_Formulas!$A:$A=LTP_Aggregated!AN7,0))} -> 0 | AP7: {=SUM(_xlfn._xlws.FILTER(LTP_Formulas!AS:AS,LTP_Formulas!$A:$A=LTP_Aggregated!AO7,0))} -> 0 | AQ7: {=SUM(_xlfn._xlws.FILTER(LTP_Formulas!AT:AT,LTP_Formulas!$A:$A=LTP_Aggregated!AP7,0))} -> 0 | AR7: {=SUM(_xlfn._xlws.FILTER(LTP_Formulas!AU:AU,LTP_Formulas!$A:$A=LTP_Aggregated!AQ7,0))} -> 0 | AS7: {=SUM(_xlfn._xlws.FILTER(LTP_Formulas!AV:AV,LTP_Formulas!$A:$A=LTP_Aggregated!AR7,0))} -> 0 | AT7: {=SUM(_xlfn._xlws.FILTER(LTP_Formulas!AW:AW,LTP_Formulas!$A:$A=LTP_Aggregated!AS7,0))} -> 0 | AU7: {=SUM(_xlfn._xlws.FILTER(LTP_Formulas!AX:AX,LTP_Formulas!$A:$A=LTP_Aggregated!AT7,0))} -> 0 | AV7: {=SUM(_xlfn._xlws.FILTER(LTP_Formulas!AY:AY,LTP_Formulas!$A:$A=LTP_Aggregated!AU7,0))} -> 0 | AW7: {=SUM(_xlfn._xlws.FILTER(LTP_Formulas!AZ:AZ,LTP_Formulas!$A:$A=LTP_Aggregated!AV7,0))} -> 0 | AX7: {=SUM(_xlfn._xlws.FILTER(LTP_Formulas!BA:BA,LTP_Formulas!$A:$A=LTP_Aggregated!AW7,0))} -> 0
A8: G_FG | B8: {=SUM(_xlfn._xlws.FILTER(LTP_Formulas!E:E,LTP_Formulas!$A:$A=LTP_Aggregated!A8,0))} -> 380 | C8: {=SUM(_xlfn._xlws.FILTER(LTP_Formulas!F:F,LTP_Formulas!$A:$A=LTP_Aggregated!B8,0))} -> 0 | D8: {=SUM(_xlfn._xlws.FILTER(LTP_Formulas!G:G,LTP_Formulas!$A:$A=LTP_Aggregated!C8,0))} -> 0 | E8: {=SUM(_xlfn._xlws.FILTER(LTP_Formulas!H:H,LTP_Formulas!$A:$A=LTP_Aggregated!D8,0))} -> 0 | F8: {=SUM(_xlfn._xlws.FILTER(LTP_Formulas!I:I,LTP_Formulas!$A:$A=LTP_Aggregated!E8,0))} -> 0 | G8: {=SUM(_xlfn._xlws.FILTER(LTP_Formulas!J:J,LTP_Formulas!$A:$A=LTP_Aggregated!F8,0))} -> 0 | H8: {=SUM(_xlfn._xlws.FILTER(LTP_Formulas!K:K,LTP_Formulas!$A:$A=LTP_Aggregated!G8,0))} -> 0 | I8: {=SUM(_xlfn._xlws.FILTER(LTP_Formulas!L:L,LTP_Formulas!$A:$A=LTP_Aggregated!H8,0))} -> 0 | J8: {=SUM(_xlfn._xlws.FILTER(LTP_Formulas!M:M,LTP_Formulas!$A:$A=LTP_Aggregated!I8,0))} -> 0 | K8: {=SUM(_xlfn._xlws.FILTER(LTP_Formulas!N:N,LTP_Formulas!$A:$A=LTP_Aggregated!J8,0))} -> 0 | L8: {=SUM(_xlfn._xlws.FILTER(LTP_Formulas!O:O,LTP_Formulas!$A:$A=LTP_Aggregated!K8,0))} -> 0 | M8: {=SUM(_xlfn._xlws.FILTER(LTP_Formulas!P:P,LTP_Formulas!$A:$A=LTP_Aggregated!L8,0))} -> 0 | N8: {=SUM(_xlfn._xlws.FILTER(LTP_Formulas!Q:Q,LTP_Formulas!$A:$A=LTP_Aggregated!M8,0))} -> 0 | O8: {=SUM(_xlfn._xlws.FILTER(LTP_Formulas!R:R,LTP_Formulas!$A:$A=LTP_Aggregated!N8,0))} -> 0 | P8: {=SUM(_xlfn._xlws.FILTER(LTP_Formulas!S:S,LTP_Formulas!$A:$A=LTP_Aggregated!O8,0))} -> 0 | Q8: {=SUM(_xlfn._xlws.FILTER(LTP_Formulas!T:T,LTP_Formulas!$A:$A=LTP_Aggregated!P8,0))} -> 0 | R8: {=SUM(_xlfn._xlws.FILTER(LTP_Formulas!U:U,LTP_Formulas!$A:$A=LTP_Aggregated!Q8,0))} -> 0 | S8: {=SUM(_xlfn._xlws.FILTER(LTP_Formulas!V:V,LTP_Formulas!$A:$A=LTP_Aggregated!R8,0))} -> 0 | T8: {=SUM(_xlfn._xlws.FILTER(LTP_Formulas!W:W,LTP_Formulas!$A:$A=LTP_Aggregated!S8,0))} -> 0 | U8: {=SUM(_xlfn._xlws.FILTER(LTP_Formulas!X:X,LTP_Formulas!$A:$A=LTP_Aggregated!T8,0))} -> 0 | V8: {=SUM(_xlfn._xlws.FILTER(LTP_Formulas!Y:Y,LTP_Formulas!$A:$A=LTP_Aggregated!U8,0))} -> 0 | W8: {=SUM(_xlfn._xlws.FILTER(LTP_Formulas!Z:Z,LTP_Formulas!$A:$A=LTP_Aggregated!V8,0))} -> 0 | X8: {=SUM(_xlfn._xlws.FILTER(LTP_Formulas!AA:AA,LTP_Formulas!$A:$A=LTP_Aggregated!W8,0))} -> 0 | Y8: {=SUM(_xlfn._xlws.FILTER(LTP_Formulas!AB:AB,LTP_Formulas!$A:$A=LTP_Aggregated!X8,0))} -> 0 | Z8: {=SUM(_xlfn._xlws.FILTER(LTP_Formulas!AC:AC,LTP_Formulas!$A:$A=LTP_Aggregated!Y8,0))} -> 0 | AA8: {=SUM(_xlfn._xlws.FILTER(LTP_Formulas!AD:AD,LTP_Formulas!$A:$A=LTP_Aggregated!Z8,0))} -> 0 | AB8: {=SUM(_xlfn._xlws.FILTER(LTP_Formulas!AE:AE,LTP_Formulas!$A:$A=LTP_Aggregated!AA8,0))} -> 0 | AC8: {=SUM(_xlfn._xlws.FILTER(LTP_Formulas!AF:AF,LTP_Formulas!$A:$A=LTP_Aggregated!AB8,0))} -> 0 | AD8: {=SUM(_xlfn._xlws.FILTER(LTP_Formulas!AG:AG,LTP_Formulas!$A:$A=LTP_Aggregated!AC8,0))} -> 0 | AE8: {=SUM(_xlfn._xlws.FILTER(LTP_Formulas!AH:AH,LTP_Formulas!$A:$A=LTP_Aggregated!AD8,0))} -> 0 | AF8: {=SUM(_xlfn._xlws.FILTER(LTP_Formulas!AI:AI,LTP_Formulas!$A:$A=LTP_Aggregated!AE8,0))} -> 0 | AG8: {=SUM(_xlfn._xlws.FILTER(LTP_Formulas!AJ:AJ,LTP_Formulas!$A:$A=LTP_Aggregated!AF8,0))} -> 0 | AH8: {=SUM(_xlfn._xlws.FILTER(LTP_Formulas!AK:AK,LTP_Formulas!$A:$A=LTP_Aggregated!AG8,0))} -> 0 | AI8: {=SUM(_xlfn._xlws.FILTER(LTP_Formulas!AL:AL,LTP_Formulas!$A:$A=LTP_Aggregated!AH8,0))} -> 0 | AJ8: {=SUM(_xlfn._xlws.FILTER(LTP_Formulas!AM:AM,LTP_Formulas!$A:$A=LTP_Aggregated!AI8,0))} -> 0 | AK8: {=SUM(_xlfn._xlws.FILTER(LTP_Formulas!AN:AN,LTP_Formulas!$A:$A=LTP_Aggregated!AJ8,0))} -> 0 | AL8: {=SUM(_xlfn._xlws.FILTER(LTP_Formulas!AO:AO,LTP_Formulas!$A:$A=LTP_Aggregated!AK8,0))} -> 0 | AM8: {=SUM(_xlfn._xlws.FILTER(LTP_Formulas!AP:AP,LTP_Formulas!$A:$A=LTP_Aggregated!AL8,0))} -> 0 | AN8: {=SUM(_xlfn._xlws.FILTER(LTP_Formulas!AQ:AQ,LTP_Formulas!$A:$A=LTP_Aggregated!AM8,0))} -> 0 | AO8: {=SUM(_xlfn._xlws.FILTER(LTP_Formulas!AR:AR,LTP_Formulas!$A:$A=LTP_Aggregated!AN8,0))} -> 0 | AP8: {=SUM(_xlfn._xlws.FILTER(LTP_Formulas!AS:AS,LTP_Formulas!$A:$A=LTP_Aggregated!AO8,0))} -> 0 | AQ8: {=SUM(_xlfn._xlws.FILTER(LTP_Formulas!AT:AT,LTP_Formulas!$A:$A=LTP_Aggregated!AP8,0))} -> 0 | AR8: {=SUM(_xlfn._xlws.FILTER(LTP_Formulas!AU:AU,LTP_Formulas!$A:$A=LTP_Aggregated!AQ8,0))} -> 0 | AS8: {=SUM(_xlfn._xlws.FILTER(LTP_Formulas!AV:AV,LTP_Formulas!$A:$A=LTP_Aggregated!AR8,0))} -> 0 | AT8: {=SUM(_xlfn._xlws.FILTER(LTP_Formulas!AW:AW,LTP_Formulas!$A:$A=LTP_Aggregated!AS8,0))} -> 0 | AU8: {=SUM(_xlfn._xlws.FILTER(LTP_Formulas!AX:AX,LTP_Formulas!$A:$A=LTP_Aggregated!AT8,0))} -> 0 | AV8: {=SUM(_xlfn._xlws.FILTER(LTP_Formulas!AY:AY,LTP_Formulas!$A:$A=LTP_Aggregated!AU8,0))} -> 0 | AW8: {=SUM(_xlfn._xlws.FILTER(LTP_Formulas!AZ:AZ,LTP_Formulas!$A:$A=LTP_Aggregated!AV8,0))} -> 0 | AX8: {=SUM(_xlfn._xlws.FILTER(LTP_Formulas!BA:BA,LTP_Formulas!$A:$A=LTP_Aggregated!AW8,0))} -> 0
A9: U_FG | B9: {=SUM(_xlfn._xlws.FILTER(LTP_Formulas!E:E,LTP_Formulas!$A:$A=LTP_Aggregated!A9,0))} -> 2678 | C9: {=SUM(_xlfn._xlws.FILTER(LTP_Formulas!F:F,LTP_Formulas!$A:$A=LTP_Aggregated!B9,0))} -> 0 | D9: {=SUM(_xlfn._xlws.FILTER(LTP_Formulas!G:G,LTP_Formulas!$A:$A=LTP_Aggregated!C9,0))} -> 0 | E9: {=SUM(_xlfn._xlws.FILTER(LTP_Formulas!H:H,LTP_Formulas!$A:$A=LTP_Aggregated!D9,0))} -> 0 | F9: {=SUM(_xlfn._xlws.FILTER(LTP_Formulas!I:I,LTP_Formulas!$A:$A=LTP_Aggregated!E9,0))} -> 0 | G9: {=SUM(_xlfn._xlws.FILTER(LTP_Formulas!J:J,LTP_Formulas!$A:$A=LTP_Aggregated!F9,0))} -> 0 | H9: {=SUM(_xlfn._xlws.FILTER(LTP_Formulas!K:K,LTP_Formulas!$A:$A=LTP_Aggregated!G9,0))} -> 0 | I9: {=SUM(_xlfn._xlws.FILTER(LTP_Formulas!L:L,LTP_Formulas!$A:$A=LTP_Aggregated!H9,0))} -> 0 | J9: {=SUM(_xlfn._xlws.FILTER(LTP_Formulas!M:M,LTP_Formulas!$A:$A=LTP_Aggregated!I9,0))} -> 0 | K9: {=SUM(_xlfn._xlws.FILTER(LTP_Formulas!N:N,LTP_Formulas!$A:$A=LTP_Aggregated!J9,0))} -> 0 | L9: {=SUM(_xlfn._xlws.FILTER(LTP_Formulas!O:O,LTP_Formulas!$A:$A=LTP_Aggregated!K9,0))} -> 0 | M9: {=SUM(_xlfn._xlws.FILTER(LTP_Formulas!P:P,LTP_Formulas!$A:$A=LTP_Aggregated!L9,0))} -> 0 | N9: {=SUM(_xlfn._xlws.FILTER(LTP_Formulas!Q:Q,LTP_Formulas!$A:$A=LTP_Aggregated!M9,0))} -> 0 | O9: {=SUM(_xlfn._xlws.FILTER(LTP_Formulas!R:R,LTP_Formulas!$A:$A=LTP_Aggregated!N9,0))} -> 0 | P9: {=SUM(_xlfn._xlws.FILTER(LTP_Formulas!S:S,LTP_Formulas!$A:$A=LTP_Aggregated!O9,0))} -> 0 | Q9: {=SUM(_xlfn._xlws.FILTER(LTP_Formulas!T:T,LTP_Formulas!$A:$A=LTP_Aggregated!P9,0))} -> 0 | R9: {=SUM(_xlfn._xlws.FILTER(LTP_Formulas!U:U,LTP_Formulas!$A:$A=LTP_Aggregated!Q9,0))} -> 0 | S9: {=SUM(_xlfn._xlws.FILTER(LTP_Formulas!V:V,LTP_Formulas!$A:$A=LTP_Aggregated!R9,0))} -> 0 | T9: {=SUM(_xlfn._xlws.FILTER(LTP_Formulas!W:W,LTP_Formulas!$A:$A=LTP_Aggregated!S9,0))} -> 0 | U9: {=SUM(_xlfn._xlws.FILTER(LTP_Formulas!X:X,LTP_Formulas!$A:$A=LTP_Aggregated!T9,0))} -> 0 | V9: {=SUM(_xlfn._xlws.FILTER(LTP_Formulas!Y:Y,LTP_Formulas!$A:$A=LTP_Aggregated!U9,0))} -> 0 | W9: {=SUM(_xlfn._xlws.FILTER(LTP_Formulas!Z:Z,LTP_Formulas!$A:$A=LTP_Aggregated!V9,0))} -> 0 | X9: {=SUM(_xlfn._xlws.FILTER(LTP_Formulas!AA:AA,LTP_Formulas!$A:$A=LTP_Aggregated!W9,0))} -> 0 | Y9: {=SUM(_xlfn._xlws.FILTER(LTP_Formulas!AB:AB,LTP_Formulas!$A:$A=LTP_Aggregated!X9,0))} -> 0 | Z9: {=SUM(_xlfn._xlws.FILTER(LTP_Formulas!AC:AC,LTP_Formulas!$A:$A=LTP_Aggregated!Y9,0))} -> 0 | AA9: {=SUM(_xlfn._xlws.FILTER(LTP_Formulas!AD:AD,LTP_Formulas!$A:$A=LTP_Aggregated!Z9,0))} -> 0 | AB9: {=SUM(_xlfn._xlws.FILTER(LTP_Formulas!AE:AE,LTP_Formulas!$A:$A=LTP_Aggregated!AA9,0))} -> 0 | AC9: {=SUM(_xlfn._xlws.FILTER(LTP_Formulas!AF:AF,LTP_Formulas!$A:$A=LTP_Aggregated!AB9,0))} -> 0 | AD9: {=SUM(_xlfn._xlws.FILTER(LTP_Formulas!AG:AG,LTP_Formulas!$A:$A=LTP_Aggregated!AC9,0))} -> 0 | AE9: {=SUM(_xlfn._xlws.FILTER(LTP_Formulas!AH:AH,LTP_Formulas!$A:$A=LTP_Aggregated!AD9,0))} -> 0 | AF9: {=SUM(_xlfn._xlws.FILTER(LTP_Formulas!AI:AI,LTP_Formulas!$A:$A=LTP_Aggregated!AE9,0))} -> 0 | AG9: {=SUM(_xlfn._xlws.FILTER(LTP_Formulas!AJ:AJ,LTP_Formulas!$A:$A=LTP_Aggregated!AF9,0))} -> 0 | AH9: {=SUM(_xlfn._xlws.FILTER(LTP_Formulas!AK:AK,LTP_Formulas!$A:$A=LTP_Aggregated!AG9,0))} -> 0 | AI9: {=SUM(_xlfn._xlws.FILTER(LTP_Formulas!AL:AL,LTP_Formulas!$A:$A=LTP_Aggregated!AH9,0))} -> 0 | AJ9: {=SUM(_xlfn._xlws.FILTER(LTP_Formulas!AM:AM,LTP_Formulas!$A:$A=LTP_Aggregated!AI9,0))} -> 0 | AK9: {=SUM(_xlfn._xlws.FILTER(LTP_Formulas!AN:AN,LTP_Formulas!$A:$A=LTP_Aggregated!AJ9,0))} -> 0 | AL9: {=SUM(_xlfn._xlws.FILTER(LTP_Formulas!AO:AO,LTP_Formulas!$A:$A=LTP_Aggregated!AK9,0))} -> 0 | AM9: {=SUM(_xlfn._xlws.FILTER(LTP_Formulas!AP:AP,LTP_Formulas!$A:$A=LTP_Aggregated!AL9,0))} -> 0 | AN9: {=SUM(_xlfn._xlws.FILTER(LTP_Formulas!AQ:AQ,LTP_Formulas!$A:$A=LTP_Aggregated!AM9,0))} -> 0 | AO9: {=SUM(_xlfn._xlws.FILTER(LTP_Formulas!AR:AR,LTP_Formulas!$A:$A=LTP_Aggregated!AN9,0))} -> 0 | AP9: {=SUM(_xlfn._xlws.FILTER(LTP_Formulas!AS:AS,LTP_Formulas!$A:$A=LTP_Aggregated!AO9,0))} -> 0 | AQ9: {=SUM(_xlfn._xlws.FILTER(LTP_Formulas!AT:AT,LTP_Formulas!$A:$A=LTP_Aggregated!AP9,0))} -> 0 | AR9: {=SUM(_xlfn._xlws.FILTER(LTP_Formulas!AU:AU,LTP_Formulas!$A:$A=LTP_Aggregated!AQ9,0))} -> 0 | AS9: {=SUM(_xlfn._xlws.FILTER(LTP_Formulas!AV:AV,LTP_Formulas!$A:$A=LTP_Aggregated!AR9,0))} -> 0 | AT9: {=SUM(_xlfn._xlws.FILTER(LTP_Formulas!AW:AW,LTP_Formulas!$A:$A=LTP_Aggregated!AS9,0))} -> 0 | AU9: {=SUM(_xlfn._xlws.FILTER(LTP_Formulas!AX:AX,LTP_Formulas!$A:$A=LTP_Aggregated!AT9,0))} -> 0 | AV9: {=SUM(_xlfn._xlws.FILTER(LTP_Formulas!AY:AY,LTP_Formulas!$A:$A=LTP_Aggregated!AU9,0))} -> 0 | AW9: {=SUM(_xlfn._xlws.FILTER(LTP_Formulas!AZ:AZ,LTP_Formulas!$A:$A=LTP_Aggregated!AV9,0))} -> 0 | AX9: {=SUM(_xlfn._xlws.FILTER(LTP_Formulas!BA:BA,LTP_Formulas!$A:$A=LTP_Aggregated!AW9,0))} -> 0
A10: E_FG | B10: {=SUM(_xlfn._xlws.FILTER(LTP_Formulas!E:E,LTP_Formulas!$A:$A=LTP_Aggregated!A10,0))} -> 1275 | C10: {=SUM(_xlfn._xlws.FILTER(LTP_Formulas!F:F,LTP_Formulas!$A:$A=LTP_Aggregated!B10,0))} -> 0 | D10: {=SUM(_xlfn._xlws.FILTER(LTP_Formulas!G:G,LTP_Formulas!$A:$A=LTP_Aggregated!C10,0))} -> 0 | E10: {=SUM(_xlfn._xlws.FILTER(LTP_Formulas!H:H,LTP_Formulas!$A:$A=LTP_Aggregated!D10,0))} -> 0 | F10: {=SUM(_xlfn._xlws.FILTER(LTP_Formulas!I:I,LTP_Formulas!$A:$A=LTP_Aggregated!E10,0))} -> 0 | G10: {=SUM(_xlfn._xlws.FILTER(LTP_Formulas!J:J,LTP_Formulas!$A:$A=LTP_Aggregated!F10,0))} -> 0 | H10: {=SUM(_xlfn._xlws.FILTER(LTP_Formulas!K:K,LTP_Formulas!$A:$A=LTP_Aggregated!G10,0))} -> 0 | I10: {=SUM(_xlfn._xlws.FILTER(LTP_Formulas!L:L,LTP_Formulas!$A:$A=LTP_Aggregated!H10,0))} -> 0 | J10: {=SUM(_xlfn._xlws.FILTER(LTP_Formulas!M:M,LTP_Formulas!$A:$A=LTP_Aggregated!I10,0))} -> 0 | K10: {=SUM(_xlfn._xlws.FILTER(LTP_Formulas!N:N,LTP_Formulas!$A:$A=LTP_Aggregated!J10,0))} -> 0 | L10: {=SUM(_xlfn._xlws.FILTER(LTP_Formulas!O:O,LTP_Formulas!$A:$A=LTP_Aggregated!K10,0))} -> 0 | M10: {=SUM(_xlfn._xlws.FILTER(LTP_Formulas!P:P,LTP_Formulas!$A:$A=LTP_Aggregated!L10,0))} -> 0 | N10: {=SUM(_xlfn._xlws.FILTER(LTP_Formulas!Q:Q,LTP_Formulas!$A:$A=LTP_Aggregated!M10,0))} -> 0 | O10: {=SUM(_xlfn._xlws.FILTER(LTP_Formulas!R:R,LTP_Formulas!$A:$A=LTP_Aggregated!N10,0))} -> 0 | P10: {=SUM(_xlfn._xlws.FILTER(LTP_Formulas!S:S,LTP_Formulas!$A:$A=LTP_Aggregated!O10,0))} -> 0 | Q10: {=SUM(_xlfn._xlws.FILTER(LTP_Formulas!T:T,LTP_Formulas!$A:$A=LTP_Aggregated!P10,0))} -> 0 | R10: {=SUM(_xlfn._xlws.FILTER(LTP_Formulas!U:U,LTP_Formulas!$A:$A=LTP_Aggregated!Q10,0))} -> 0 | S10: {=SUM(_xlfn._xlws.FILTER(LTP_Formulas!V:V,LTP_Formulas!$A:$A=LTP_Aggregated!R10,0))} -> 0 | T10: {=SUM(_xlfn._xlws.FILTER(LTP_Formulas!W:W,LTP_Formulas!$A:$A=LTP_Aggregated!S10,0))} -> 0 | U10: {=SUM(_xlfn._xlws.FILTER(LTP_Formulas!X:X,LTP_Formulas!$A:$A=LTP_Aggregated!T10,0))} -> 0 | V10: {=SUM(_xlfn._xlws.FILTER(LTP_Formulas!Y:Y,LTP_Formulas!$A:$A=LTP_Aggregated!U10,0))} -> 0 | W10: {=SUM(_xlfn._xlws.FILTER(LTP_Formulas!Z:Z,LTP_Formulas!$A:$A=LTP_Aggregated!V10,0))} -> 0 | X10: {=SUM(_xlfn._xlws.FILTER(LTP_Formulas!AA:AA,LTP_Formulas!$A:$A=LTP_Aggregated!W10,0))} -> 0 | Y10: {=SUM(_xlfn._xlws.FILTER(LTP_Formulas!AB:AB,LTP_Formulas!$A:$A=LTP_Aggregated!X10,0))} -> 0 | Z10: {=SUM(_xlfn._xlws.FILTER(LTP_Formulas!AC:AC,LTP_Formulas!$A:$A=LTP_Aggregated!Y10,0))} -> 0 | AA10: {=SUM(_xlfn._xlws.FILTER(LTP_Formulas!AD:AD,LTP_Formulas!$A:$A=LTP_Aggregated!Z10,0))} -> 0 | AB10: {=SUM(_xlfn._xlws.FILTER(LTP_Formulas!AE:AE,LTP_Formulas!$A:$A=LTP_Aggregated!AA10,0))} -> 0 | AC10: {=SUM(_xlfn._xlws.FILTER(LTP_Formulas!AF:AF,LTP_Formulas!$A:$A=LTP_Aggregated!AB10,0))} -> 0 | AD10: {=SUM(_xlfn._xlws.FILTER(LTP_Formulas!AG:AG,LTP_Formulas!$A:$A=LTP_Aggregated!AC10,0))} -> 0 | AE10: {=SUM(_xlfn._xlws.FILTER(LTP_Formulas!AH:AH,LTP_Formulas!$A:$A=LTP_Aggregated!AD10,0))} -> 0 | AF10: {=SUM(_xlfn._xlws.FILTER(LTP_Formulas!AI:AI,LTP_Formulas!$A:$A=LTP_Aggregated!AE10,0))} -> 0 | AG10: {=SUM(_xlfn._xlws.FILTER(LTP_Formulas!AJ:AJ,LTP_Formulas!$A:$A=LTP_Aggregated!AF10,0))} -> 0 | AH10: {=SUM(_xlfn._xlws.FILTER(LTP_Formulas!AK:AK,LTP_Formulas!$A:$A=LTP_Aggregated!AG10,0))} -> 0 | AI10: {=SUM(_xlfn._xlws.FILTER(LTP_Formulas!AL:AL,LTP_Formulas!$A:$A=LTP_Aggregated!AH10,0))} -> 0 | AJ10: {=SUM(_xlfn._xlws.FILTER(LTP_Formulas!AM:AM,LTP_Formulas!$A:$A=LTP_Aggregated!AI10,0))} -> 0 | AK10: {=SUM(_xlfn._xlws.FILTER(LTP_Formulas!AN:AN,LTP_Formulas!$A:$A=LTP_Aggregated!AJ10,0))} -> 0 | AL10: {=SUM(_xlfn._xlws.FILTER(LTP_Formulas!AO:AO,LTP_Formulas!$A:$A=LTP_Aggregated!AK10,0))} -> 0 | AM10: {=SUM(_xlfn._xlws.FILTER(LTP_Formulas!AP:AP,LTP_Formulas!$A:$A=LTP_Aggregated!AL10,0))} -> 0 | AN10: {=SUM(_xlfn._xlws.FILTER(LTP_Formulas!AQ:AQ,LTP_Formulas!$A:$A=LTP_Aggregated!AM10,0))} -> 0 | AO10: {=SUM(_xlfn._xlws.FILTER(LTP_Formulas!AR:AR,LTP_Formulas!$A:$A=LTP_Aggregated!AN10,0))} -> 0 | AP10: {=SUM(_xlfn._xlws.FILTER(LTP_Formulas!AS:AS,LTP_Formulas!$A:$A=LTP_Aggregated!AO10,0))} -> 0 | AQ10: {=SUM(_xlfn._xlws.FILTER(LTP_Formulas!AT:AT,LTP_Formulas!$A:$A=LTP_Aggregated!AP10,0))} -> 0 | AR10: {=SUM(_xlfn._xlws.FILTER(LTP_Formulas!AU:AU,LTP_Formulas!$A:$A=LTP_Aggregated!AQ10,0))} -> 0 | AS10: {=SUM(_xlfn._xlws.FILTER(LTP_Formulas!AV:AV,LTP_Formulas!$A:$A=LTP_Aggregated!AR10,0))} -> 0 | AT10: {=SUM(_xlfn._xlws.FILTER(LTP_Formulas!AW:AW,LTP_Formulas!$A:$A=LTP_Aggregated!AS10,0))} -> 0 | AU10: {=SUM(_xlfn._xlws.FILTER(LTP_Formulas!AX:AX,LTP_Formulas!$A:$A=LTP_Aggregated!AT10,0))} -> 0 | AV10: {=SUM(_xlfn._xlws.FILTER(LTP_Formulas!AY:AY,LTP_Formulas!$A:$A=LTP_Aggregated!AU10,0))} -> 0 | AW10: {=SUM(_xlfn._xlws.FILTER(LTP_Formulas!AZ:AZ,LTP_Formulas!$A:$A=LTP_Aggregated!AV10,0))} -> 0 | AX10: {=SUM(_xlfn._xlws.FILTER(LTP_Formulas!BA:BA,LTP_Formulas!$A:$A=LTP_Aggregated!AW10,0))} -> 0
A11: R_FG | B11: {=SUM(_xlfn._xlws.FILTER(LTP_Formulas!E:E,LTP_Formulas!$A:$A=LTP_Aggregated!A11,0))} -> 1499 | C11: {=SUM(_xlfn._xlws.FILTER(LTP_Formulas!F:F,LTP_Formulas!$A:$A=LTP_Aggregated!B11,0))} -> 0 | D11: {=SUM(_xlfn._xlws.FILTER(LTP_Formulas!G:G,LTP_Formulas!$A:$A=LTP_Aggregated!C11,0))} -> 0 | E11: {=SUM(_xlfn._xlws.FILTER(LTP_Formulas!H:H,LTP_Formulas!$A:$A=LTP_Aggregated!D11,0))} -> 0 | F11: {=SUM(_xlfn._xlws.FILTER(LTP_Formulas!I:I,LTP_Formulas!$A:$A=LTP_Aggregated!E11,0))} -> 0 | G11: {=SUM(_xlfn._xlws.FILTER(LTP_Formulas!J:J,LTP_Formulas!$A:$A=LTP_Aggregated!F11,0))} -> 0 | H11: {=SUM(_xlfn._xlws.FILTER(LTP_Formulas!K:K,LTP_Formulas!$A:$A=LTP_Aggregated!G11,0))} -> 0 | I11: {=SUM(_xlfn._xlws.FILTER(LTP_Formulas!L:L,LTP_Formulas!$A:$A=LTP_Aggregated!H11,0))} -> 0 | J11: {=SUM(_xlfn._xlws.FILTER(LTP_Formulas!M:M,LTP_Formulas!$A:$A=LTP_Aggregated!I11,0))} -> 0 | K11: {=SUM(_xlfn._xlws.FILTER(LTP_Formulas!N:N,LTP_Formulas!$A:$A=LTP_Aggregated!J11,0))} -> 0 | L11: {=SUM(_xlfn._xlws.FILTER(LTP_Formulas!O:O,LTP_Formulas!$A:$A=LTP_Aggregated!K11,0))} -> 0 | M11: {=SUM(_xlfn._xlws.FILTER(LTP_Formulas!P:P,LTP_Formulas!$A:$A=LTP_Aggregated!L11,0))} -> 0 | N11: {=SUM(_xlfn._xlws.FILTER(LTP_Formulas!Q:Q,LTP_Formulas!$A:$A=LTP_Aggregated!M11,0))} -> 0 | O11: {=SUM(_xlfn._xlws.FILTER(LTP_Formulas!R:R,LTP_Formulas!$A:$A=LTP_Aggregated!N11,0))} -> 0 | P11: {=SUM(_xlfn._xlws.FILTER(LTP_Formulas!S:S,LTP_Formulas!$A:$A=LTP_Aggregated!O11,0))} -> 0 | Q11: {=SUM(_xlfn._xlws.FILTER(LTP_Formulas!T:T,LTP_Formulas!$A:$A=LTP_Aggregated!P11,0))} -> 0 | R11: {=SUM(_xlfn._xlws.FILTER(LTP_Formulas!U:U,LTP_Formulas!$A:$A=LTP_Aggregated!Q11,0))} -> 0 | S11: {=SUM(_xlfn._xlws.FILTER(LTP_Formulas!V:V,LTP_Formulas!$A:$A=LTP_Aggregated!R11,0))} -> 0 | T11: {=SUM(_xlfn._xlws.FILTER(LTP_Formulas!W:W,LTP_Formulas!$A:$A=LTP_Aggregated!S11,0))} -> 0 | U11: {=SUM(_xlfn._xlws.FILTER(LTP_Formulas!X:X,LTP_Formulas!$A:$A=LTP_Aggregated!T11,0))} -> 0 | V11: {=SUM(_xlfn._xlws.FILTER(LTP_Formulas!Y:Y,LTP_Formulas!$A:$A=LTP_Aggregated!U11,0))} -> 0 | W11: {=SUM(_xlfn._xlws.FILTER(LTP_Formulas!Z:Z,LTP_Formulas!$A:$A=LTP_Aggregated!V11,0))} -> 0 | X11: {=SUM(_xlfn._xlws.FILTER(LTP_Formulas!AA:AA,LTP_Formulas!$A:$A=LTP_Aggregated!W11,0))} -> 0 | Y11: {=SUM(_xlfn._xlws.FILTER(LTP_Formulas!AB:AB,LTP_Formulas!$A:$A=LTP_Aggregated!X11,0))} -> 0 | Z11: {=SUM(_xlfn._xlws.FILTER(LTP_Formulas!AC:AC,LTP_Formulas!$A:$A=LTP_Aggregated!Y11,0))} -> 0 | AA11: {=SUM(_xlfn._xlws.FILTER(LTP_Formulas!AD:AD,LTP_Formulas!$A:$A=LTP_Aggregated!Z11,0))} -> 0 | AB11: {=SUM(_xlfn._xlws.FILTER(LTP_Formulas!AE:AE,LTP_Formulas!$A:$A=LTP_Aggregated!AA11,0))} -> 0 | AC11: {=SUM(_xlfn._xlws.FILTER(LTP_Formulas!AF:AF,LTP_Formulas!$A:$A=LTP_Aggregated!AB11,0))} -> 0 | AD11: {=SUM(_xlfn._xlws.FILTER(LTP_Formulas!AG:AG,LTP_Formulas!$A:$A=LTP_Aggregated!AC11,0))} -> 0 | AE11: {=SUM(_xlfn._xlws.FILTER(LTP_Formulas!AH:AH,LTP_Formulas!$A:$A=LTP_Aggregated!AD11,0))} -> 0 | AF11: {=SUM(_xlfn._xlws.FILTER(LTP_Formulas!AI:AI,LTP_Formulas!$A:$A=LTP_Aggregated!AE11,0))} -> 0 | AG11: {=SUM(_xlfn._xlws.FILTER(LTP_Formulas!AJ:AJ,LTP_Formulas!$A:$A=LTP_Aggregated!AF11,0))} -> 0 | AH11: {=SUM(_xlfn._xlws.FILTER(LTP_Formulas!AK:AK,LTP_Formulas!$A:$A=LTP_Aggregated!AG11,0))} -> 0 | AI11: {=SUM(_xlfn._xlws.FILTER(LTP_Formulas!AL:AL,LTP_Formulas!$A:$A=LTP_Aggregated!AH11,0))} -> 0 | AJ11: {=SUM(_xlfn._xlws.FILTER(LTP_Formulas!AM:AM,LTP_Formulas!$A:$A=LTP_Aggregated!AI11,0))} -> 0 | AK11: {=SUM(_xlfn._xlws.FILTER(LTP_Formulas!AN:AN,LTP_Formulas!$A:$A=LTP_Aggregated!AJ11,0))} -> 0 | AL11: {=SUM(_xlfn._xlws.FILTER(LTP_Formulas!AO:AO,LTP_Formulas!$A:$A=LTP_Aggregated!AK11,0))} -> 0 | AM11: {=SUM(_xlfn._xlws.FILTER(LTP_Formulas!AP:AP,LTP_Formulas!$A:$A=LTP_Aggregated!AL11,0))} -> 0 | AN11: {=SUM(_xlfn._xlws.FILTER(LTP_Formulas!AQ:AQ,LTP_Formulas!$A:$A=LTP_Aggregated!AM11,0))} -> 0 | AO11: {=SUM(_xlfn._xlws.FILTER(LTP_Formulas!AR:AR,LTP_Formulas!$A:$A=LTP_Aggregated!AN11,0))} -> 0 | AP11: {=SUM(_xlfn._xlws.FILTER(LTP_Formulas!AS:AS,LTP_Formulas!$A:$A=LTP_Aggregated!AO11,0))} -> 0 | AQ11: {=SUM(_xlfn._xlws.FILTER(LTP_Formulas!AT:AT,LTP_Formulas!$A:$A=LTP_Aggregated!AP11,0))} -> 0 | AR11: {=SUM(_xlfn._xlws.FILTER(LTP_Formulas!AU:AU,LTP_Formulas!$A:$A=LTP_Aggregated!AQ11,0))} -> 0 | AS11: {=SUM(_xlfn._xlws.FILTER(LTP_Formulas!AV:AV,LTP_Formulas!$A:$A=LTP_Aggregated!AR11,0))} -> 0 | AT11: {=SUM(_xlfn._xlws.FILTER(LTP_Formulas!AW:AW,LTP_Formulas!$A:$A=LTP_Aggregated!AS11,0))} -> 0 | AU11: {=SUM(_xlfn._xlws.FILTER(LTP_Formulas!AX:AX,LTP_Formulas!$A:$A=LTP_Aggregated!AT11,0))} -> 0 | AV11: {=SUM(_xlfn._xlws.FILTER(LTP_Formulas!AY:AY,LTP_Formulas!$A:$A=LTP_Aggregated!AU11,0))} -> 0 | AW11: {=SUM(_xlfn._xlws.FILTER(LTP_Formulas!AZ:AZ,LTP_Formulas!$A:$A=LTP_Aggregated!AV11,0))} -> 0 | AX11: {=SUM(_xlfn._xlws.FILTER(LTP_Formulas!BA:BA,LTP_Formulas!$A:$A=LTP_Aggregated!AW11,0))} -> 0
